Workbook

Sheet 📋 Инструкция
B2: 🍏 ЗЕЛЕНОЕ ЯБЛОКО - Калькулятор цен, маржи и сценариев v1.0
B4: НАЗНАЧЕНИЕ ФАЙЛА
B5: Инструмент для коммерческого блока: анализ цены, наценки, маржи, сравнение с рынком и сценарное моделирование по всем позициям.
B7: ЛИСТЫ ФАЙЛА
B8: 📊 Исходные данные - товарная матрица: цены ЗЯ и конкурентов. Загружается из исходного файла.
B9: 🛒 Продажи - продажи по штрихкоду (кол-во, выручка, ВП). Опционально.
B10: 🔢 Расчеты - все автоматические формулы. Ручной ввод только в синих ячейках.
B11: 📈 Dashboard - KPI-карточки, светофоры, топы. Обновляется автоматически.
B12: 📋 Сценарный анализ - сводная таблица по 5 сценариям и автоматические рекомендации.
B14: ПОЛЯ РУЧНОГО ВВОДА (синий цвет = вводить вручную)
B15: Лист «🛒 Продажи»: Штрихкод, Кол-во продаж, Выручка, Валовая прибыль.
B16: Лист «Расчеты», колонка T (Кол-во продаж) - можно вводить прямо здесь.
... B27: ЦВЕТОВЫЕ ОБОЗНАЧЕНИЯ
B28: Синий текст | E28: Поле ручного ввода - вводить вручную
B29: Черный текст | E29: Формула - не изменять
B30: Зеленый фон | E30: Цена ниже рынка / хорошая маржа
B31: Красный фон | E31: Цена выше рынка / риск потери маржи
B32: Желтый фон | E32: Нейтральная зона / требует внимания
B34: НАВИГАЦИЯ
B35: 📊 Исходные данные
B36: 🛒 Продажи
B37: 🔢 Расчеты
B38: 📈 Dashboard
B39: 📋 Сценарный анализ

Sheet 📊 Исходные данные
A1: Наименование | B1: Штрихкод | C1: Закупочная_цена | D1: Розничная_цена_ЗЯ | E1: Цена_7_Континент | F1: Цена_Европейский | G1: Цена_Тропики | H1: Цена_Мята | I1: Цена_Отличный | J1: Цена_Оптовик_Молоток | K1: Цена_Оптовик_Редукторный
A2: Белизна гипохлорид 1л | B2: 4665272570017 | C2: 29 | D2: 39 | F2: 55 | I2: 52 | J2: 41
A3: Гель белизна Санфор 3в1 700мл | B3: 4602984001637 | C3: 87.83 | D3: 119 | H3: 131 | J3: 110
A4: Гель Ласка 1л для Черного Эффект восстановления | B4: 9000101409321 | C4: 236.18 | D4: 339 | F4: 349 | H4: 301 | J4: 265
A5: Кондиционер ABC для белья 1440мл Элегантная Орхидея | B5: 8690511000983 | C5: 235 | D5: 289 | F5: 285 | H5: 288 | J5: 240 | K5: 230
A6: Порошок ABC авт 3кг Лимон | B6: 8690511171614 | C6: 255 | D6: 385 | F6: 356 | H6: 394 | I6: 329 | K6: 299
A7: Порошок Ариэль авт 3кг Колор | B7: 5413149333437 | C7: 496.63 | D7: 599 | E7: 673 | H7: 540 | J7: 490
A8: Отбеливатель Бос плюс Макс 500г | B8: 4600905000332 | C8: 127 | D8: 179 | I8: 191
A9: Средство AOS для посуды 450г Лимон | B9: 4604049012305 | C9: 67.94 | D9: 85 | E9: 107 | H9: 85 | I9: 88 | J9: 80 | K9: 71
A10: Средство AOS для посуды 900г Лимон | B10: 4604049095476 | C10: 131.78 | D10: 199 | H10: 169 | I10: 179 | J10: 140 | K10: 138
A11: Средство Грасс Azelit Антижир для кухни спрей 600мл | B11: 4607072197537 | C11: 116.07 | D11: 159 | E11: 157 | H11: 157 | J11: 125
A12: Средство Доместос 1,5л Ультра блеск | B12: 8714100797525 | C12: 160.16 | D12: 249
A13: Средство Доместос 500мл Ультра блеск | B13: 8714100707890 | C13: 77.02 | D13: 139 | H13: 124 | J13: 105
A14: Кассеты для бритья Жиллетт Фьюжн 4шт | B14: 7702018874460
A15: Зубная паста Сплат Профессионал 100г Отбеливание плюс | B15: 4603014023704
A16: Мыло жидкое Грасс Milana 1000мл Perfume | B16: 4670113604165
A17: Салфетки влажные Мануоки детские 80шт | B17: 4620174812764
A18: Полотенца бумажные Папия Декор 3 слоя 2 рулона | B18: 4604857001782 | C18: 99.19 | D18: 129 | F18: 134 | H18: 127 | I18: 139 | J18: 100
A19: Туалетная бумага Папия 3сл 4рул белая | B19: 8690536023936
A20: Полотенца бумажные Zemma 2сл 2рул | B20: 4670199857349 | C20: 77 | D20: 99
A21: Туалетная бумага Zemma Плюс 2сл 4шт Белая | B21: 4605331003308 | C21: 77 | D21: 99 | H21: 95 | J21: 90
A22: Крупа Гречневая (ядрица) Первый сорт 1кг | B22: 2057030071836 | C22: 48 | D22: 59 | E22: 75 | I22: 61 | J22: 60
A23: Крупа Рисовая (рис шлифованный) 1кг | B23: 2058077055810 | C23: 60 | D23: 79 | E23: 87 | I23: 91 | J23: 80 | K23: 80
A24: Крупа Увелка Гречневая Экстра 800г | B24: 4607016240893 | C24: 71.35 | D24: 89 | E24: 99 | F24: 94 | G24: 100 | H24: 89 | I24: 91 | J24: 90
A25: Мак изд Барилла №5 Спагетти 450г | B25: 8076809576093 | C25: 81.79 | D25: 119 | E25: 95 | F25: 100 | G25: 135 | H25: 94 | I25: 96 | J25: 105 | K25: 92
A26: Мак изд Барилла №98 Фузилли 450г | B26: 8076809576000 | C26: 81.79 | D26: 119 | E26: 108 | F26: 109 | G26: 115 | H26: 122 | I26: 199 | J26: 105 | K26: 92
A27: Мак изд Макфа Спагетти 400г | B27: 4601780010508 | C27: 49.51 | D27: 65 | E27: 68 | F27: 64 | H27: 77 | I27: 61 | J27: 80 | K27: 57
A28: Мак изд Макфа Спирали 400г | B28: 4601780006990 | C28: 49.51 | D28: 65 | E28: 68 | F28: 64 | G28: 68 | H28: 63 | I28: 62 | J28: 62 | K28: 56
A29: Мука Макфа в/с 2кг | B29: 4601780002565 | C29: 93 | D29: 119 | E29: 139 | F29: 107 | G29: 140 | H29: 157 | I29: 108 | J29: 130
A30: Мука Снежана в/с 2кг | B30: 1905000299036 | C30: 83.16 | D30: 99 | G30: 110 | H30: 116 | I30: 108 | J30: 90
A31: Рис Агроальянс для плова 900г | B31: 4607072711535 | C31: 116.5 | D31: 135 | F31: 202 | I31: 197 | J31: 145
A32: Рис Дарман шлифованный Премиум 2кг | B32: 4607157483784 | C32: 240 | D32: 299 | F32: 310 | I32: 293 | J32: 265
A33: Рис Дарман шлифованный Экстра 800г | B33: 4607157483029 | C33: 91.5 | D33: 115 | E33: 113 | F33: 123 | G33: 120 | J33: 110
A34: Рис Тамаша MIAD Индия мешочек 1кг | B34: 8906010700720 | C34: 165 | D34: 249 | E34: 250 | G34: 245 | H34: 244 | I34: 238 | J34: 230
A35: Сахар песок 1кг | B35: 2067468029354 | C35: 58.9 | D35: 65 | E35: 60 | F35: 64 | G35: 85 | I35: 78 | J35: 80
A36: Сода пищевая 500г | B36: 4640001890031 | C36: 38.16 | D36: 55 | E36: 55 | F36: 56 | G36: 55 | H36: 52 | I36: 53 | J36: 50
A37: Соль поваренная пищевая Помол №1 1кг Руссоль | B37: 4610007350228 | C37: 9.32 | D37: 17 | E37: 28 | F37: 22 | G37: 20 | H37: 19 | I37: 21 | J37: 18 | K37: 16
A38: Соль Экстра йодированная 500г | B38: 4607005090126 | C38: 65.38 | D38: 85 | F38: 84 | I38: 81 | J38: 55
A39: Пюре Агуша фруктовое пауч 160г Яблоко банан клубн земляника злаки | B39: 4690228110771 | C39: 63.16 | D39: 79 | H39: 76 | I39: 80 | J39: 75
A40: Пюре ФрутоНяня 90г Яблоко натур. 4 мес д/пак | B40: 4600338006130 | C40: 47.48 | D40: 59 | J40: 45
...

Sheet 🛒 Продажи
A1: Штрихкод | B1: Кол-во_продаж | C1: Выручка | D1: Валовая_прибыль
A13: Заполните по штрихкоду. При отсутствии данных - расчёты на листе Расчеты работают без ошибок.

Sheet 🔢 Расчеты
A1: ИДЕНТИФИКАЦИЯ | C1: ЦЕНЫ ЗЯ / СИГНАЛ | F1: АНАЛИЗ РЫНКА | O1: ЭКОНОМИКА ТЕКУЩАЯ | T1: ПРОДАЖИ | X1: С1: СРЕДНЯЯ РЫНКА | AE1: С2: МЕДИАНА РЫНКА | AL1: С3: МИН.КОНКУРЕНТ | AS1: С4: ПРОИЗВ.ЦЕНА | AZ1: С5: ЦЕЛЕВАЯ МАРЖА | BH1: МОДЕЛИРОВАНИЕ ПРОДАЖ
A2: Наименование | B2: Штрихкод | C2: Закупочная цена | D2: Розничная цена ЗЯ | E2: Сигнал цены | F2: Ср.цена рынка | G2: Медиана рынка | H2: Мин.конкурент | I2: Макс.конкурент | J2: Откл.от средней | K2: Откл.от медианы | L2: Откл.от минимума | M2: Рейтинг цены | N2: Позиц.на рынке | O2: Наценка тек.% | P2: Маржа тек.% | Q2: ВП/ед тек. | R2: Сигнал маржи | S2: Риск потери ВП | T2: Кол-во продаж | U2: Выручка тек. | V2: ВП тек.суммарная | W2: Маржа тек.общая% | X2: С1:Цена | Y2: С1:Наценка% | Z2: С1:Маржа% | AA2: С1:ВП/ед | AB2: С1:Дельта цены% | AC2: С1:Дельта маржи% | AD2: С1:Дельта ВП/ед | AE2: С2:Цена | AF2: С2:Наценка% | AG2: С2:Маржа% | AH2: С2:ВП/ед | AI2: С2:Дельта цены% | AJ2: С2:Дельта маржи% | AK2: С2:Дельта ВП/ед | AL2: С3:Цена | AM2: С3:Наценка% | AN2: С3:Маржа% | AO2: С3:ВП/ед | AP2: С3:Дельта цены% | AQ2: С3:Дельта маржи% | AR2: С3:Дельта ВП/ед | AS2: С4:Нов.цена[ВВОД] | AT2: С4:Наценка% | AU2: С4:Маржа% | AV2: С4:ВП/ед | AW2: С4:Дельта цены% | AX2: С4:Дельта маржи% | AY2: С4:Дельта ВП/ед | AZ2: С5:Цел.маржа[ВВОД] | BA2: С5:Цена | BB2: С5:Наценка% | BC2: С5:Маржа% | BD2: С5:ВП/ед | BE2: С5:Дельта цены% | BF2: С5:Дельта маржи% | BG2: С5:Дельта ВП/ед | BH2: С1:Прогн.выручка | BI2: С1:Прогн.ВП | BJ2: С2:Прогн.выручка | BK2: С2:Прогн.ВП | BL2: С3:Прогн.выручка | BM2: С3:Прогн.ВП | BN2: С4:Прогн.выручка | BO2: С4:Прогн.ВП | BP2: С5:Прогн.выручка | BQ2: С5:Прогн.ВП | BR2: С1:Треб.рост шт | BS2: С1:Треб.рост % | BT2: С3:Треб.рост шт | BU2: С3:Треб.рост %
A3: ='📊 Исходные данные'!A2 | B3: ='📊 Исходные данные'!B2 | C3: ='📊 Исходные данные'!C2 | D3: ='📊 Исходные данные'!D2 | E3: =IF(OR(D3="",F3=""),"-",IF(D3>F3*1.05,"Выше рынка",IF(D3<F3*0.95,"Ниже рынка","На уровне"))) | F3: =IFERROR(AVERAGE('📊 Исходные данные'!E2,'📊 Исходные данные'!F2,'📊 Исходные данные'!G2,'📊 Исходные данные'!H2,'📊 Исходные данные'!I2,'📊 Исходные данные'!J2,'📊 Исходные данные'!K2),"") | G3: =IFERROR(MEDIAN('📊 Исходные данные'!E2,'📊 Исходные данные'!F2,'📊 Исходные данные'!G2,'📊 Исходные данные'!H2,'📊 Исходные данные'!I2,'📊 Исходные данные'!J2,'📊 Исходные данные'!K2),"") | H3: =IFERROR(MIN('📊 Исходные данные'!E2,'📊 Исходные данные'!F2,'📊 Исходные данные'!G2,'📊 Исходные данные'!H2,'📊 Исходные данные'!I2,'📊 Исходные данные'!J2,'📊 Исходные данные'!K2),"") | I3: =IFERROR(MAX('📊 Исходные данные'!E2,'📊 Исходные данные'!F2,'📊 Исходные данные'!G2,'📊 Исходные данные'!H2,'📊 Исходные данные'!I2,'📊 Исходные данные'!J2,'📊 Исходные данные'!K2),"") | J3: =IF(AND(D3<>"",F3<>""),(D3-F3)/F3,"") | K3: =IF(AND(D3<>"",G3<>""),(D3-G3)/G3,"") | L3: =IF(AND(D3<>"",H3<>""),(D3-H3)/H3,"") | M3: =IFERROR(RANK(D3,('📊 Исходные данные'!E2,'📊 Исходные данные'!F2,'📊 Исходные данные'!G2,'📊 Исходные данные'!H2,'📊 Исходные данные'!I2,'📊 Исходные данные'!J2,'📊 Исходные данные'!K2)),"") | N3: =IF(M3="","-",IF(M3=1,"Дороже всех",IF(M3=2,"2-й по цене",IF(M3<=4,"Средний","Ниже конкурентов")))) | O3: =IF(AND(C3>0,D3>0),(D3-C3)/C3,"") | P3: =IF(AND(C3>0,D3>0),(D3-C3)/D3,"") | Q3: =IF(AND(C3>0,D3>0),D3-C3,"") | R3: =IF(P3="","-",IF(P3<0.1,"Низкая(<10%)",IF(P3<0.2,"Средняя(10-20%)","Хорошая(>20%)"))) | S3: =IF(OR(H3="",C3=""),"-",IF((H3-C3)/H3<0.05,"КРИТИЧНО",IF((H3-C3)/H3<0.15,"УМЕРЕННЫЙ","НИЗКИЙ"))) | U3: =IF(T3>0,T3*D3,"") | V3: =IF(T3>0,T3*Q3,"") | W3: =IF(U3>0,V3/U3,"") | X3: =IF(F3<>"",F3,"") | Y3: =IF(AND(X3<>"",C3>0),(X3-C3)/C3,"") | Z3: =IF(AND(X3<>"",X3>0),(X3-C3)/X3,"") | AA3: =IF(AND(X3<>"",C3>0),X3-C3,"") | AB3: =IF(AND(X3<>"",D3>0),(X3-D3)/D3,"") | AC3: =IF(AND(Z3<>"",P3<>""),(Z3-P3)/ABS(IF(P3=0,1,P3)),"") | AD3: =IF(AND(AA3<>"",Q3<>""),AA3-Q3,"") | AE3: =IF(G3<>"",G3,"") | AF3: =IF(AND(AE3<>"",C3>0),(AE3-C3)/C3,"") | AG3: =IF(AND(AE3<>"",AE3>0),(AE3-C3)/AE3,"") | AH3: =IF(AND(AE3<>"",C3>0),AE3-C3,"") | AI3: =IF(AND(AE3<>"",D3>0),(AE3-D3)/D3,"") | AJ3: =IF(AND(AG3<>"",P3<>""),(AG3-P3)/ABS(IF(P3=0,1,P3)),"") | AK3: =IF(AND(AH3<>"",Q3<>""),AH3-Q3,"") | AL3: =IF(H3<>"",H3,"") | AM3: =IF(AND(AL3<>"",C3>0),(AL3-C3)/C3,"") | AN3: =IF(AND(AL3<>"",AL3>0),(AL3-C3)/AL3,"") | AO3: =IF(AND(AL3<>"",C3>0),AL3-C3,"") | AP3: =IF(AND(AL3<>"",D3>0),(AL3-D3)/D3,"") | AQ3: =IF(AND(AN3<>"",P3<>""),(AN3-P3)/ABS(IF(P3=0,1,P3)),"") | AR3: =IF(AND(AO3<>"",Q3<>""),AO3-Q3,"") | AT3: =IF(AND(AS3>0,C3>0),(AS3-C3)/C3,"") | AU3: =IF(AND(AS3>0,AS3>0),(AS3-C3)/AS3,"") | AV3: =IF(AND(AS3>0,C3>0),AS3-C3,"") | AW3: =IF(AND(AS3>0,D3>0),(AS3-D3)/D3,"") | AX3: =IF(AND(AU3<>"",P3<>""),(AU3-P3)/ABS(IF(P3=0,1,P3)),"") | AY3: =IF(AND(AV3<>"",Q3<>""),AV3-Q3,"") | BA3: =IF(AND(AZ3>0,C3>0),C3/(1-AZ3),"") | BB3: =IF(AND(BA3<>"",C3>0),(BA3-C3)/C3,"") | BC3: =IF(BA3<>"",AZ3,"") | BD3: =IF(AND(BA3<>"",C3>0),BA3-C3,"") | BE3: =IF(AND(BA3<>"",D3>0),(BA3-D3)/D3,"") | BF3: =IF(AND(BC3<>"",P3<>""),(BC3-P3)/ABS(IF(P3=0,1,P3)),"") | BG3: =IF(AND(BD3<>"",Q3<>""),BD3-Q3,"") | BH3: =IF(AND(T3>0,X3<>""),T3*X3,"") | BI3: =IF(AND(T3>0,AA3<>""),T3*AA3,"") | BJ3: =IF(AND(T3>0,AE3<>""),T3*AE3,"") | BK3: =IF(AND(T3>0,AH3<>""),T3*AH3,"") | BL3: =IF(AND(T3>0,AL3<>""),T3*AL3,"") | BM3: =IF(AND(T3>0,AO3<>""),T3*AO3,"") | BN3: =IF(AND(T3>0,AS3>0),T3*AS3,"") | BO3: =IF(AND(T3>0,AV3<>""),T3*AV3,"") | BP3: =IF(AND(T3>0,BA3<>""),T3*BA3,"") | BQ3: =IF(AND(T3>0,BD3<>""),T3*BD3,"") | BR3: =IF(AND(T3>0,V3>0,AA3<>0),V3/AA3-T3,"") | BS3: =IF(AND(BR3<>"",T3>0),BR3/T3,"") | BT3: =IF(AND(T3>0,V3>0,AO3<>0),V3/AO3-T3,"") | BU3: =IF(AND(BT3<>"",T3>0),BT3/T3,"")
A4: ='📊 Исходные данные'!A3 | B4: ='📊 Исходные данные'!B3 | C4: ='📊 Исходные данные'!C3 | D4: ='📊 Исходные данные'!D3 | E4: =IF(OR(D4="",F4=""),"-",IF(D4>F4*1.05,"Выше рынка",IF(D4<F4*0.95,"Ниже рынка","На уровне"))) | F4: =IFERROR(AVERAGE('📊 Исходные данные'!E3,'📊 Исходные данные'!F3,'📊 Исходные данные'!G3,'📊 Исходные данные'!H3,'📊 Исходные данные'!I3,'📊 Исходные данные'!J3,'📊 Исходные данные'!K3),"") | G4: =IFERROR(MEDIAN('📊 Исходные данные'!E3,'📊 Исходные данные'!F3,'📊 Исходные данные'!G3,'📊 Исходные данные'!H3,'📊 Исходные данные'!I3,'📊 Исходные данные'!J3,'📊 Исходные данные'!K3),"") | H4: =IFERROR(MIN('📊 Исходные данные'!E3,'📊 Исходные данные'!F3,'📊 Исходные данные'!G3,'📊 Исходные данные'!H3,'📊 Исходные данные'!I3,'📊 Исходные данные'!J3,'📊 Исходные данные'!K3),"") | I4: =IFERROR(MAX('📊 Исходные данные'!E3,'📊 Исходные данные'!F3,'📊 Исходные данные'!G3,'📊 Исходные данные'!H3,'📊 Исходные данные'!I3,'📊 Исходные данные'!J3,'📊 Исходные данные'!K3),"") | J4: =IF(AND(D4<>"",F4<>""),(D4-F4)/F4,"") | K4: =IF(AND(D4<>"",G4<>""),(D4-G4)/G4,"") | L4: =IF(AND(D4<>"",H4<>""),(D4-H4)/H4,"") | M4: =IFERROR(RANK(D4,('📊 Исходные данные'!E3,'📊 Исходные данные'!F3,'📊 Исходные данные'!G3,'📊 Исходные данные'!H3,'📊 Исходные данные'!I3,'📊 Исходные данные'!J3,'📊 Исходные данные'!K3)),"") | N4: =IF(M4="","-",IF(M4=1,"Дороже всех",IF(M4=2,"2-й по цене",IF(M4<=4,"Средний","Ниже конкурентов")))) | O4: =IF(AND(C4>0,D4>0),(D4-C4)/C4,"") | P4: =IF(AND(C4>0,D4>0),(D4-C4)/D4,"") | Q4: =IF(AND(C4>0,D4>0),D4-C4,"") | R4: =IF(P4="","-",IF(P4<0.1,"Низкая(<10%)",IF(P4<0.2,"Средняя(10-20%)","Хорошая(>20%)"))) | S4: =IF(OR(H4="",C4=""),"-",IF((H4-C4)/H4<0.05,"КРИТИЧНО",IF((H4-C4)/H4<0.15,"УМЕРЕННЫЙ","НИЗКИЙ"))) | U4: =IF(T4>0,T4*D4,"") | V4: =IF(T4>0,T4*Q4,"") | W4: =IF(U4>0,V4/U4,"") | X4: =IF(F4<>"",F4,"") | Y4: =IF(AND(X4<>"",C4>0),(X4-C4)/C4,"") | Z4: =IF(AND(X4<>"",X4>0),(X4-C4)/X4,"") | AA4: =IF(AND(X4<>"",C4>0),X4-C4,"") | AB4: =IF(AND(X4<>"",D4>0),(X4-D4)/D4,"") | AC4: =IF(AND(Z4<>"",P4<>""),(Z4-P4)/ABS(IF(P4=0,1,P4)),"") | AD4: =IF(AND(AA4<>"",Q4<>""),AA4-Q4,"") | AE4: =IF(G4<>"",G4,"") | AF4: =IF(AND(AE4<>"",C4>0),(AE4-C4)/C4,"") | AG4: =IF(AND(AE4<>"",AE4>0),(AE4-C4)/AE4,"") | AH4: =IF(AND(AE4<>"",C4>0),AE4-C4,"") | AI4: =IF(AND(AE4<>"",D4>0),(AE4-D4)/D4,"") | AJ4: =IF(AND(AG4<>"",P4<>""),(AG4-P4)/ABS(IF(P4=0,1,P4)),"") | AK4: =IF(AND(AH4<>"",Q4<>""),AH4-Q4,"") | AL4: =IF(H4<>"",H4,"") | AM4: =IF(AND(AL4<>"",C4>0),(AL4-C4)/C4,"") | AN4: =IF(AND(AL4<>"",AL4>0),(AL4-C4)/AL4,"") | AO4: =IF(AND(AL4<>"",C4>0),AL4-C4,"") | AP4: =IF(AND(AL4<>"",D4>0),(AL4-D4)/D4,"") | AQ4: =IF(AND(AN4<>"",P4<>""),(AN4-P4)/ABS(IF(P4=0,1,P4)),"") | AR4: =IF(AND(AO4<>"",Q4<>""),AO4-Q4,"") | AT4: =IF(AND(AS4>0,C4>0),(AS4-C4)/C4,"") | AU4: =IF(AND(AS4>0,AS4>0),(AS4-C4)/AS4,"") | AV4: =IF(AND(AS4>0,C4>0),AS4-C4,"") | AW4: =IF(AND(AS4>0,D4>0),(AS4-D4)/D4,"") | AX4: =IF(AND(AU4<>"",P4<>""),(AU4-P4)/ABS(IF(P4=0,1,P4)),"") | AY4: =IF(AND(AV4<>"",Q4<>""),AV4-Q4,"") | BA4: =IF(AND(AZ4>0,C4>0),C4/(1-AZ4),"") | BB4: =IF(AND(BA4<>"",C4>0),(BA4-C4)/C4,"") | BC4: =IF(BA4<>"",AZ4,"") | BD4: =IF(AND(BA4<>"",C4>0),BA4-C4,"") | BE4: =IF(AND(BA4<>"",D4>0),(BA4-D4)/D4,"") | BF4: =IF(AND(BC4<>"",P4<>""),(BC4-P4)/ABS(IF(P4=0,1,P4)),"") | BG4: =IF(AND(BD4<>"",Q4<>""),BD4-Q4,"") | BH4: =IF(AND(T4>0,X4<>""),T4*X4,"") | BI4: =IF(AND(T4>0,AA4<>""),T4*AA4,"") | BJ4: =IF(AND(T4>0,AE4<>""),T4*AE4,"") | BK4: =IF(AND(T4>0,AH4<>""),T4*AH4,"") | BL4: =IF(AND(T4>0,AL4<>""),T4*AL4,"") | BM4: =IF(AND(T4>0,AO4<>""),T4*AO4,"") | BN4: =IF(AND(T4>0,AS4>0),T4*AS4,"") | BO4: =IF(AND(T4>0,AV4<>""),T4*AV4,"") | BP4: =IF(AND(T4>0,BA4<>""),T4*BA4,"") | BQ4: =IF(AND(T4>0,BD4<>""),T4*BD4,"") | BR4: =IF(AND(T4>0,V4>0,AA4<>0),V4/AA4-T4,"") | BS4: =IF(AND(BR4<>"",T4>0),BR4/T4,"") | BT4: =IF(AND(T4>0,V4>0,AO4<>0),V4/AO4-T4,"") | BU4: =IF(AND(BT4<>"",T4>0),BT4/T4,"")
A5: ='📊 Исходные данные'!A4 | B5: ='📊 Исходные данные'!B4 | C5: ='📊 Исходные данные'!C4 | D5: ='📊 Исходные данные'!D4 | E5: =IF(OR(D5="",F5=""),"-",IF(D5>F5*1.05,"Выше рынка",IF(D5<F5*0.95,"Ниже рынка","На уровне"))) | F5: =IFERROR(AVERAGE('📊 Исходные данные'!E4,'📊 Исходные данные'!F4,'📊 Исходные данные'!G4,'📊 Исходные данные'!H4,'📊 Исходные данные'!I4,'📊 Исходные данные'!J4,'📊 Исходные данные'!K4),"") | G5: =IFERROR(MEDIAN('📊 Исходные данные'!E4,'📊 Исходные данные'!F4,'📊 Исходные данные'!G4,'📊 Исходные данные'!H4,'📊 Исходные данные'!I4,'📊 Исходные данные'!J4,'📊 Исходные данные'!K4),"") | H5: =IFERROR(MIN('📊 Исходные данные'!E4,'📊 Исходные данные'!F4,'📊 Исходные данные'!G4,'📊 Исходные данные'!H4,'📊 Исходные данные'!I4,'📊 Исходные данные'!J4,'📊 Исходные данные'!K4),"") | I5: =IFERROR(MAX('📊 Исходные данные'!E4,'📊 Исходные данные'!F4,'📊 Исходные данные'!G4,'📊 Исходные данные'!H4,'📊 Исходные данные'!I4,'📊 Исходные данные'!J4,'📊 Исходные данные'!K4),"") | J5: =IF(AND(D5<>"",F5<>""),(D5-F5)/F5,"") | K5: =IF(AND(D5<>"",G5<>""),(D5-G5)/G5,"") | L5: =IF(AND(D5<>"",H5<>""),(D5-H5)/H5,"") | M5: =IFERROR(RANK(D5,('📊 Исходные данные'!E4,'📊 Исходные данные'!F4,'📊 Исходные данные'!G4,'📊 Исходные данные'!H4,'📊 Исходные данные'!I4,'📊 Исходные данные'!J4,'📊 Исходные данные'!K4)),"") | N5: =IF(M5="","-",IF(M5=1,"Дороже всех",IF(M5=2,"2-й по цене",IF(M5<=4,"Средний","Ниже конкурентов")))) | O5: =IF(AND(C5>0,D5>0),(D5-C5)/C5,"") | P5: =IF(AND(C5>0,D5>0),(D5-C5)/D5,"") | Q5: =IF(AND(C5>0,D5>0),D5-C5,"") | R5: =IF(P5="","-",IF(P5<0.1,"Низкая(<10%)",IF(P5<0.2,"Средняя(10-20%)","Хорошая(>20%)"))) | S5: =IF(OR(H5="",C5=""),"-",IF((H5-C5)/H5<0.05,"КРИТИЧНО",IF((H5-C5)/H5<0.15,"УМЕРЕННЫЙ","НИЗКИЙ"))) | U5: =IF(T5>0,T5*D5,"") | V5: =IF(T5>0,T5*Q5,"") | W5: =IF(U5>0,V5/U5,"") | X5: =IF(F5<>"",F5,"") | Y5: =IF(AND(X5<>"",C5>0),(X5-C5)/C5,"") | Z5: =IF(AND(X5<>"",X5>0),(X5-C5)/X5,"") | AA5: =IF(AND(X5<>"",C5>0),X5-C5,"") | AB5: =IF(AND(X5<>"",D5>0),(X5-D5)/D5,"") | AC5: =IF(AND(Z5<>"",P5<>""),(Z5-P5)/ABS(IF(P5=0,1,P5)),"") | AD5: =IF(AND(AA5<>"",Q5<>""),AA5-Q5,"") | AE5: =IF(G5<>"",G5,"") | AF5: =IF(AND(AE5<>"",C5>0),(AE5-C5)/C5,"") | AG5: =IF(AND(AE5<>"",AE5>0),(AE5-C5)/AE5,"") | AH5: =IF(AND(AE5<>"",C5>0),AE5-C5,"") | AI5: =IF(AND(AE5<>"",D5>0),(AE5-D5)/D5,"") | AJ5: =IF(AND(AG5<>"",P5<>""),(AG5-P5)/ABS(IF(P5=0,1,P5)),"") | AK5: =IF(AND(AH5<>"",Q5<>""),AH5-Q5,"") | AL5: =IF(H5<>"",H5,"") | AM5: =IF(AND(AL5<>"",C5>0),(AL5-C5)/C5,"") | AN5: =IF(AND(AL5<>"",AL5>0),(AL5-C5)/AL5,"") | AO5: =IF(AND(AL5<>"",C5>0),AL5-C5,"") | AP5: =IF(AND(AL5<>"",D5>0),(AL5-D5)/D5,"") | AQ5: =IF(AND(AN5<>"",P5<>""),(AN5-P5)/ABS(IF(P5=0,1,P5)),"") | AR5: =IF(AND(AO5<>"",Q5<>""),AO5-Q5,"") | AT5: =IF(AND(AS5>0,C5>0),(AS5-C5)/C5,"") | AU5: =IF(AND(AS5>0,AS5>0),(AS5-C5)/AS5,"") | AV5: =IF(AND(AS5>0,C5>0),AS5-C5,"") | AW5: =IF(AND(AS5>0,D5>0),(AS5-D5)/D5,"") | AX5: =IF(AND(AU5<>"",P5<>""),(AU5-P5)/ABS(IF(P5=0,1,P5)),"") | AY5: =IF(AND(AV5<>"",Q5<>""),AV5-Q5,"") | BA5: =IF(AND(AZ5>0,C5>0),C5/(1-AZ5),"") | BB5: =IF(AND(BA5<>"",C5>0),(BA5-C5)/C5,"") | BC5: =IF(BA5<>"",AZ5,"") | BD5: =IF(AND(BA5<>"",C5>0),BA5-C5,"") | BE5: =IF(AND(BA5<>"",D5>0),(BA5-D5)/D5,"") | BF5: =IF(AND(BC5<>"",P5<>""),(BC5-P5)/ABS(IF(P5=0,1,P5)),"") | BG5: =IF(AND(BD5<>"",Q5<>""),BD5-Q5,"") | BH5: =IF(AND(T5>0,X5<>""),T5*X5,"") | BI5: =IF(AND(T5>0,AA5<>""),T5*AA5,"") | BJ5: =IF(AND(T5>0,AE5<>""),T5*AE5,"") | BK5: =IF(AND(T5>0,AH5<>""),T5*AH5,"") | BL5: =IF(AND(T5>0,AL5<>""),T5*AL5,"") | BM5: =IF(AND(T5>0,AO5<>""),T5*AO5,"") | BN5: =IF(AND(T5>0,AS5>0),T5*AS5,"") | BO5: =IF(AND(T5>0,AV5<>""),T5*AV5,"") | BP5: =IF(AND(T5>0,BA5<>""),T5*BA5,"") | BQ5: =IF(AND(T5>0,BD5<>""),T5*BD5,"") | BR5: =IF(AND(T5>0,V5>0,AA5<>0),V5/AA5-T5,"") | BS5: =IF(AND(BR5<>"",T5>0),BR5/T5,"") | BT5: =IF(AND(T5>0,V5>0,AO5<>0),V5/AO5-T5,"") | BU5: =IF(AND(BT5<>"",T5>0),BT5/T5,"")
A6: ='📊 Исходные данные'!A5 | B6: ='📊 Исходные данные'!B5 | C6: ='📊 Исходные данные'!C5 | D6: ='📊 Исходные данные'!D5 | E6: =IF(OR(D6="",F6=""),"-",IF(D6>F6*1.05,"Выше рынка",IF(D6<F6*0.95,"Ниже рынка","На уровне"))) | F6: =IFERROR(AVERAGE('📊 Исходные данные'!E5,'📊 Исходные данные'!F5,'📊 Исходные данные'!G5,'📊 Исходные данные'!H5,'📊 Исходные данные'!I5,'📊 Исходные данные'!J5,'📊 Исходные данные'!K5),"") | G6: =IFERROR(MEDIAN('📊 Исходные данные'!E5,'📊 Исходные данные'!F5,'📊 Исходные данные'!G5,'📊 Исходные данные'!H5,'📊 Исходные данные'!I5,'📊 Исходные данные'!J5,'📊 Исходные данные'!K5),"") | H6: =IFERROR(MIN('📊 Исходные данные'!E5,'📊 Исходные данные'!F5,'📊 Исходные данные'!G5,'📊 Исходные данные'!H5,'📊 Исходные данные'!I5,'📊 Исходные данные'!J5,'📊 Исходные данные'!K5),"") | I6: =IFERROR(MAX('📊 Исходные данные'!E5,'📊 Исходные данные'!F5,'📊 Исходные данные'!G5,'📊 Исходные данные'!H5,'📊 Исходные данные'!I5,'📊 Исходные данные'!J5,'📊 Исходные данные'!K5),"") | J6: =IF(AND(D6<>"",F6<>""),(D6-F6)/F6,"") | K6: =IF(AND(D6<>"",G6<>""),(D6-G6)/G6,"") | L6: =IF(AND(D6<>"",H6<>""),(D6-H6)/H6,"") | M6: =IFERROR(RANK(D6,('📊 Исходные данные'!E5,'📊 Исходные данные'!F5,'📊 Исходные данные'!G5,'📊 Исходные данные'!H5,'📊 Исходные данные'!I5,'📊 Исходные данные'!J5,'📊 Исходные данные'!K5)),"") | N6: =IF(M6="","-",IF(M6=1,"Дороже всех",IF(M6=2,"2-й по цене",IF(M6<=4,"Средний","Ниже конкурентов")))) | O6: =IF(AND(C6>0,D6>0),(D6-C6)/C6,"") | P6: =IF(AND(C6>0,D6>0),(D6-C6)/D6,"") | Q6: =IF(AND(C6>0,D6>0),D6-C6,"") | R6: =IF(P6="","-",IF(P6<0.1,"Низкая(<10%)",IF(P6<0.2,"Средняя(10-20%)","Хорошая(>20%)"))) | S6: =IF(OR(H6="",C6=""),"-",IF((H6-C6)/H6<0.05,"КРИТИЧНО",IF((H6-C6)/H6<0.15,"УМЕРЕННЫЙ","НИЗКИЙ"))) | U6: =IF(T6>0,T6*D6,"") | V6: =IF(T6>0,T6*Q6,"") | W6: =IF(U6>0,V6/U6,"") | X6: =IF(F6<>"",F6,"") | Y6: =IF(AND(X6<>"",C6>0),(X6-C6)/C6,"") | Z6: =IF(AND(X6<>"",X6>0),(X6-C6)/X6,"") | AA6: =IF(AND(X6<>"",C6>0),X6-C6,"") | AB6: =IF(AND(X6<>"",D6>0),(X6-D6)/D6,"") | AC6: =IF(AND(Z6<>"",P6<>""),(Z6-P6)/ABS(IF(P6=0,1,P6)),"") | AD6: =IF(AND(AA6<>"",Q6<>""),AA6-Q6,"") | AE6: =IF(G6<>"",G6,"") | AF6: =IF(AND(AE6<>"",C6>0),(AE6-C6)/C6,"") | AG6: =IF(AND(AE6<>"",AE6>0),(AE6-C6)/AE6,"") | AH6: =IF(AND(AE6<>"",C6>0),AE6-C6,"") | AI6: =IF(AND(AE6<>"",D6>0),(AE6-D6)/D6,"") | AJ6: =IF(AND(AG6<>"",P6<>""),(AG6-P6)/ABS(IF(P6=0,1,P6)),"") | AK6: =IF(AND(AH6<>"",Q6<>""),AH6-Q6,"") | AL6: =IF(H6<>"",H6,"") | AM6: =IF(AND(AL6<>"",C6>0),(AL6-C6)/C6,"") | AN6: =IF(AND(AL6<>"",AL6>0),(AL6-C6)/AL6,"") | AO6: =IF(AND(AL6<>"",C6>0),AL6-C6,"") | AP6: =IF(AND(AL6<>"",D6>0),(AL6-D6)/D6,"") | AQ6: =IF(AND(AN6<>"",P6<>""),(AN6-P6)/ABS(IF(P6=0,1,P6)),"") | AR6: =IF(AND(AO6<>"",Q6<>""),AO6-Q6,"") | AT6: =IF(AND(AS6>0,C6>0),(AS6-C6)/C6,"") | AU6: =IF(AND(AS6>0,AS6>0),(AS6-C6)/AS6,"") | AV6: =IF(AND(AS6>0,C6>0),AS6-C6,"") | AW6: =IF(AND(AS6>0,D6>0),(AS6-D6)/D6,"") | AX6: =IF(AND(AU6<>"",P6<>""),(AU6-P6)/ABS(IF(P6=0,1,P6)),"") | AY6: =IF(AND(AV6<>"",Q6<>""),AV6-Q6,"") | BA6: =IF(AND(AZ6>0,C6>0),C6/(1-AZ6),"") | BB6: =IF(AND(BA6<>"",C6>0),(BA6-C6)/C6,"") | BC6: =IF(BA6<>"",AZ6,"") | BD6: =IF(AND(BA6<>"",C6>0),BA6-C6,"") | BE6: =IF(AND(BA6<>"",D6>0),(BA6-D6)/D6,"") | BF6: =IF(AND(BC6<>"",P6<>""),(BC6-P6)/ABS(IF(P6=0,1,P6)),"") | BG6: =IF(AND(BD6<>"",Q6<>""),BD6-Q6,"") | BH6: =IF(AND(T6>0,X6<>""),T6*X6,"") | BI6: =IF(AND(T6>0,AA6<>""),T6*AA6,"") | BJ6: =IF(AND(T6>0,AE6<>""),T6*AE6,"") | BK6: =IF(AND(T6>0,AH6<>""),T6*AH6,"") | BL6: =IF(AND(T6>0,AL6<>""),T6*AL6,"") | BM6: =IF(AND(T6>0,AO6<>""),T6*AO6,"") | BN6: =IF(AND(T6>0,AS6>0),T6*AS6,"") | BO6: =IF(AND(T6>0,AV6<>""),T6*AV6,"") | BP6: =IF(AND(T6>0,BA6<>""),T6*BA6,"") | BQ6: =IF(AND(T6>0,BD6<>""),T6*BD6,"") | BR6: =IF(AND(T6>0,V6>0,AA6<>0),V6/AA6-T6,"") | BS6: =IF(AND(BR6<>"",T6>0),BR6/T6,"") | BT6: =IF(AND(T6>0,V6>0,AO6<>0),V6/AO6-T6,"") | BU6: =IF(AND(BT6<>"",T6>0),BT6/T6,"")
A7: ='📊 Исходные данные'!A6 | B7: ='📊 Исходные данные'!B6 | C7: ='📊 Исходные данные'!C6 | D7: ='📊 Исходные данные'!D6 | E7: =IF(OR(D7="",F7=""),"-",IF(D7>F7*1.05,"Выше рынка",IF(D7<F7*0.95,"Ниже рынка","На уровне"))) | F7: =IFERROR(AVERAGE('📊 Исходные данные'!E6,'📊 Исходные данные'!F6,'📊 Исходные данные'!G6,'📊 Исходные данные'!H6,'📊 Исходные данные'!I6,'📊 Исходные данные'!J6,'📊 Исходные данные'!K6),"") | G7: =IFERROR(MEDIAN('📊 Исходные данные'!E6,'📊 Исходные данные'!F6,'📊 Исходные данные'!G6,'📊 Исходные данные'!H6,'📊 Исходные данные'!I6,'📊 Исходные данные'!J6,'📊 Исходные данные'!K6),"") | H7: =IFERROR(MIN('📊 Исходные данные'!E6,'📊 Исходные данные'!F6,'📊 Исходные данные'!G6,'📊 Исходные данные'!H6,'📊 Исходные данные'!I6,'📊 Исходные данные'!J6,'📊 Исходные данные'!K6),"") | I7: =IFERROR(MAX('📊 Исходные данные'!E6,'📊 Исходные данные'!F6,'📊 Исходные данные'!G6,'📊 Исходные данные'!H6,'📊 Исходные данные'!I6,'📊 Исходные данные'!J6,'📊 Исходные данные'!K6),"") | J7: =IF(AND(D7<>"",F7<>""),(D7-F7)/F7,"") | K7: =IF(AND(D7<>"",G7<>""),(D7-G7)/G7,"") | L7: =IF(AND(D7<>"",H7<>""),(D7-H7)/H7,"") | M7: =IFERROR(RANK(D7,('📊 Исходные данные'!E6,'📊 Исходные данные'!F6,'📊 Исходные данные'!G6,'📊 Исходные данные'!H6,'📊 Исходные данные'!I6,'📊 Исходные данные'!J6,'📊 Исходные данные'!K6)),"") | N7: =IF(M7="","-",IF(M7=1,"Дороже всех",IF(M7=2,"2-й по цене",IF(M7<=4,"Средний","Ниже конкурентов")))) | O7: =IF(AND(C7>0,D7>0),(D7-C7)/C7,"") | P7: =IF(AND(C7>0,D7>0),(D7-C7)/D7,"") | Q7: =IF(AND(C7>0,D7>0),D7-C7,"") | R7: =IF(P7="","-",IF(P7<0.1,"Низкая(<10%)",IF(P7<0.2,"Средняя(10-20%)","Хорошая(>20%)"))) | S7: =IF(OR(H7="",C7=""),"-",IF((H7-C7)/H7<0.05,"КРИТИЧНО",IF((H7-C7)/H7<0.15,"УМЕРЕННЫЙ","НИЗКИЙ"))) | U7: =IF(T7>0,T7*D7,"") | V7: =IF(T7>0,T7*Q7,"") | W7: =IF(U7>0,V7/U7,"") | X7: =IF(F7<>"",F7,"") | Y7: =IF(AND(X7<>"",C7>0),(X7-C7)/C7,"") | Z7: =IF(AND(X7<>"",X7>0),(X7-C7)/X7,"") | AA7: =IF(AND(X7<>"",C7>0),X7-C7,"") | AB7: =IF(AND(X7<>"",D7>0),(X7-D7)/D7,"") | AC7: =IF(AND(Z7<>"",P7<>""),(Z7-P7)/ABS(IF(P7=0,1,P7)),"") | AD7: =IF(AND(AA7<>"",Q7<>""),AA7-Q7,"") | AE7: =IF(G7<>"",G7,"") | AF7: =IF(AND(AE7<>"",C7>0),(AE7-C7)/C7,"") | AG7: =IF(AND(AE7<>"",AE7>0),(AE7-C7)/AE7,"") | AH7: =IF(AND(AE7<>"",C7>0),AE7-C7,"") | AI7: =IF(AND(AE7<>"",D7>0),(AE7-D7)/D7,"") | AJ7: =IF(AND(AG7<>"",P7<>""),(AG7-P7)/ABS(IF(P7=0,1,P7)),"") | AK7: =IF(AND(AH7<>"",Q7<>""),AH7-Q7,"") | AL7: =IF(H7<>"",H7,"") | AM7: =IF(AND(AL7<>"",C7>0),(AL7-C7)/C7,"") | AN7: =IF(AND(AL7<>"",AL7>0),(AL7-C7)/AL7,"") | AO7: =IF(AND(AL7<>"",C7>0),AL7-C7,"") | AP7: =IF(AND(AL7<>"",D7>0),(AL7-D7)/D7,"") | AQ7: =IF(AND(AN7<>"",P7<>""),(AN7-P7)/ABS(IF(P7=0,1,P7)),"") | AR7: =IF(AND(AO7<>"",Q7<>""),AO7-Q7,"") | AT7: =IF(AND(AS7>0,C7>0),(AS7-C7)/C7,"") | AU7: =IF(AND(AS7>0,AS7>0),(AS7-C7)/AS7,"") | AV7: =IF(AND(AS7>0,C7>0),AS7-C7,"") | AW7: =IF(AND(AS7>0,D7>0),(AS7-D7)/D7,"") | AX7: =IF(AND(AU7<>"",P7<>""),(AU7-P7)/ABS(IF(P7=0,1,P7)),"") | AY7: =IF(AND(AV7<>"",Q7<>""),AV7-Q7,"") | BA7: =IF(AND(AZ7>0,C7>0),C7/(1-AZ7),"") | BB7: =IF(AND(BA7<>"",C7>0),(BA7-C7)/C7,"") | BC7: =IF(BA7<>"",AZ7,"") | BD7: =IF(AND(BA7<>"",C7>0),BA7-C7,"") | BE7: =IF(AND(BA7<>"",D7>0),(BA7-D7)/D7,"") | BF7: =IF(AND(BC7<>"",P7<>""),(BC7-P7)/ABS(IF(P7=0,1,P7)),"") | BG7: =IF(AND(BD7<>"",Q7<>""),BD7-Q7,"") | BH7: =IF(AND(T7>0,X7<>""),T7*X7,"") | BI7: =IF(AND(T7>0,AA7<>""),T7*AA7,"") | BJ7: =IF(AND(T7>0,AE7<>""),T7*AE7,"") | BK7: =IF(AND(T7>0,AH7<>""),T7*AH7,"") | BL7: =IF(AND(T7>0,AL7<>""),T7*AL7,"") | BM7: =IF(AND(T7>0,AO7<>""),T7*AO7,"") | BN7: =IF(AND(T7>0,AS7>0),T7*AS7,"") | BO7: =IF(AND(T7>0,AV7<>""),T7*AV7,"") | BP7: =IF(AND(T7>0,BA7<>""),T7*BA7,"") | BQ7: =IF(AND(T7>0,BD7<>""),T7*BD7,"") | BR7: =IF(AND(T7>0,V7>0,AA7<>0),V7/AA7-T7,"") | BS7: =IF(AND(BR7<>"",T7>0),BR7/T7,"") | BT7: =IF(AND(T7>0,V7>0,AO7<>0),V7/AO7-T7,"") | BU7: =IF(AND(BT7<>"",T7>0),BT7/T7,"")
A8: ='📊 Исходные данные'!A7 | B8: ='📊 Исходные данные'!B7 | C8: ='📊 Исходные данные'!C7 | D8: ='📊 Исходные данные'!D7 | E8: =IF(OR(D8="",F8=""),"-",IF(D8>F8*1.05,"Выше рынка",IF(D8<F8*0.95,"Ниже рынка","На уровне"))) | F8: =IFERROR(AVERAGE('📊 Исходные данные'!E7,'📊 Исходные данные'!F7,'📊 Исходные данные'!G7,'📊 Исходные данные'!H7,'📊 Исходные данные'!I7,'📊 Исходные данные'!J7,'📊 Исходные данные'!K7),"") | G8: =IFERROR(MEDIAN('📊 Исходные данные'!E7,'📊 Исходные данные'!F7,'📊 Исходные данные'!G7,'📊 Исходные данные'!H7,'📊 Исходные данные'!I7,'📊 Исходные данные'!J7,'📊 Исходные данные'!K7),"") | H8: =IFERROR(MIN('📊 Исходные данные'!E7,'📊 Исходные данные'!F7,'📊 Исходные данные'!G7,'📊 Исходные данные'!H7,'📊 Исходные данные'!I7,'📊 Исходные данные'!J7,'📊 Исходные данные'!K7),"") | I8: =IFERROR(MAX('📊 Исходные данные'!E7,'📊 Исходные данные'!F7,'📊 Исходные данные'!G7,'📊 Исходные данные'!H7,'📊 Исходные данные'!I7,'📊 Исходные данные'!J7,'📊 Исходные данные'!K7),"") | J8: =IF(AND(D8<>"",F8<>""),(D8-F8)/F8,"") | K8: =IF(AND(D8<>"",G8<>""),(D8-G8)/G8,"") | L8: =IF(AND(D8<>"",H8<>""),(D8-H8)/H8,"") | M8: =IFERROR(RANK(D8,('📊 Исходные данные'!E7,'📊 Исходные данные'!F7,'📊 Исходные данные'!G7,'📊 Исходные данные'!H7,'📊 Исходные данные'!I7,'📊 Исходные данные'!J7,'📊 Исходные данные'!K7)),"") | N8: =IF(M8="","-",IF(M8=1,"Дороже всех",IF(M8=2,"2-й по цене",IF(M8<=4,"Средний","Ниже конкурентов")))) | O8: =IF(AND(C8>0,D8>0),(D8-C8)/C8,"") | P8: =IF(AND(C8>0,D8>0),(D8-C8)/D8,"") | Q8: =IF(AND(C8>0,D8>0),D8-C8,"") | R8: =IF(P8="","-",IF(P8<0.1,"Низкая(<10%)",IF(P8<0.2,"Средняя(10-20%)","Хорошая(>20%)"))) | S8: =IF(OR(H8="",C8=""),"-",IF((H8-C8)/H8<0.05,"КРИТИЧНО",IF((H8-C8)/H8<0.15,"УМЕРЕННЫЙ","НИЗКИЙ"))) | U8: =IF(T8>0,T8*D8,"") | V8: =IF(T8>0,T8*Q8,"") | W8: =IF(U8>0,V8/U8,"") | X8: =IF(F8<>"",F8,"") | Y8: =IF(AND(X8<>"",C8>0),(X8-C8)/C8,"") | Z8: =IF(AND(X8<>"",X8>0),(X8-C8)/X8,"") | AA8: =IF(AND(X8<>"",C8>0),X8-C8,"") | AB8: =IF(AND(X8<>"",D8>0),(X8-D8)/D8,"") | AC8: =IF(AND(Z8<>"",P8<>""),(Z8-P8)/ABS(IF(P8=0,1,P8)),"") | AD8: =IF(AND(AA8<>"",Q8<>""),AA8-Q8,"") | AE8: =IF(G8<>"",G8,"") | AF8: =IF(AND(AE8<>"",C8>0),(AE8-C8)/C8,"") | AG8: =IF(AND(AE8<>"",AE8>0),(AE8-C8)/AE8,"") | AH8: =IF(AND(AE8<>"",C8>0),AE8-C8,"") | AI8: =IF(AND(AE8<>"",D8>0),(AE8-D8)/D8,"") | AJ8: =IF(AND(AG8<>"",P8<>""),(AG8-P8)/ABS(IF(P8=0,1,P8)),"") | AK8: =IF(AND(AH8<>"",Q8<>""),AH8-Q8,"") | AL8: =IF(H8<>"",H8,"") | AM8: =IF(AND(AL8<>"",C8>0),(AL8-C8)/C8,"") | AN8: =IF(AND(AL8<>"",AL8>0),(AL8-C8)/AL8,"") | AO8: =IF(AND(AL8<>"",C8>0),AL8-C8,"") | AP8: =IF(AND(AL8<>"",D8>0),(AL8-D8)/D8,"") | AQ8: =IF(AND(AN8<>"",P8<>""),(AN8-P8)/ABS(IF(P8=0,1,P8)),"") | AR8: =IF(AND(AO8<>"",Q8<>""),AO8-Q8,"") | AT8: =IF(AND(AS8>0,C8>0),(AS8-C8)/C8,"") | AU8: =IF(AND(AS8>0,AS8>0),(AS8-C8)/AS8,"") | AV8: =IF(AND(AS8>0,C8>0),AS8-C8,"") | AW8: =IF(AND(AS8>0,D8>0),(AS8-D8)/D8,"") | AX8: =IF(AND(AU8<>"",P8<>""),(AU8-P8)/ABS(IF(P8=0,1,P8)),"") | AY8: =IF(AND(AV8<>"",Q8<>""),AV8-Q8,"") | BA8: =IF(AND(AZ8>0,C8>0),C8/(1-AZ8),"") | BB8: =IF(AND(BA8<>"",C8>0),(BA8-C8)/C8,"") | BC8: =IF(BA8<>"",AZ8,"") | BD8: =IF(AND(BA8<>"",C8>0),BA8-C8,"") | BE8: =IF(AND(BA8<>"",D8>0),(BA8-D8)/D8,"") | BF8: =IF(AND(BC8<>"",P8<>""),(BC8-P8)/ABS(IF(P8=0,1,P8)),"") | BG8: =IF(AND(BD8<>"",Q8<>""),BD8-Q8,"") | BH8: =IF(AND(T8>0,X8<>""),T8*X8,"") | BI8: =IF(AND(T8>0,AA8<>""),T8*AA8,"") | BJ8: =IF(AND(T8>0,AE8<>""),T8*AE8,"") | BK8: =IF(AND(T8>0,AH8<>""),T8*AH8,"") | BL8: =IF(AND(T8>0,AL8<>""),T8*AL8,"") | BM8: =IF(AND(T8>0,AO8<>""),T8*AO8,"") | BN8: =IF(AND(T8>0,AS8>0),T8*AS8,"") | BO8: =IF(AND(T8>0,AV8<>""),T8*AV8,"") | BP8: =IF(AND(T8>0,BA8<>""),T8*BA8,"") | BQ8: =IF(AND(T8>0,BD8<>""),T8*BD8,"") | BR8: =IF(AND(T8>0,V8>0,AA8<>0),V8/AA8-T8,"") | BS8: =IF(AND(BR8<>"",T8>0),BR8/T8,"") | BT8: =IF(AND(T8>0,V8>0,AO8<>0),V8/AO8-T8,"") | BU8: =IF(AND(BT8<>"",T8>0),BT8/T8,"")
A9: ='📊 Исходные данные'!A8 | B9: ='📊 Исходные данные'!B8 | C9: ='📊 Исходные данные'!C8 | D9: ='📊 Исходные данные'!D8 | E9: =IF(OR(D9="",F9=""),"-",IF(D9>F9*1.05,"Выше рынка",IF(D9<F9*0.95,"Ниже рынка","На уровне"))) | F9: =IFERROR(AVERAGE('📊 Исходные данные'!E8,'📊 Исходные данные'!F8,'📊 Исходные данные'!G8,'📊 Исходные данные'!H8,'📊 Исходные данные'!I8,'📊 Исходные данные'!J8,'📊 Исходные данные'!K8),"") | G9: =IFERROR(MEDIAN('📊 Исходные данные'!E8,'📊 Исходные данные'!F8,'📊 Исходные данные'!G8,'📊 Исходные данные'!H8,'📊 Исходные данные'!I8,'📊 Исходные данные'!J8,'📊 Исходные данные'!K8),"") | H9: =IFERROR(MIN('📊 Исходные данные'!E8,'📊 Исходные данные'!F8,'📊 Исходные данные'!G8,'📊 Исходные данные'!H8,'📊 Исходные данные'!I8,'📊 Исходные данные'!J8,'📊 Исходные данные'!K8),"") | I9: =IFERROR(MAX('📊 Исходные данные'!E8,'📊 Исходные данные'!F8,'📊 Исходные данные'!G8,'📊 Исходные данные'!H8,'📊 Исходные данные'!I8,'📊 Исходные данные'!J8,'📊 Исходные данные'!K8),"") | J9: =IF(AND(D9<>"",F9<>""),(D9-F9)/F9,"") | K9: =IF(AND(D9<>"",G9<>""),(D9-G9)/G9,"") | L9: =IF(AND(D9<>"",H9<>""),(D9-H9)/H9,"") | M9: =IFERROR(RANK(D9,('📊 Исходные данные'!E8,'📊 Исходные данные'!F8,'📊 Исходные данные'!G8,'📊 Исходные данные'!H8,'📊 Исходные данные'!I8,'📊 Исходные данные'!J8,'📊 Исходные данные'!K8)),"") | N9: =IF(M9="","-",IF(M9=1,"Дороже всех",IF(M9=2,"2-й по цене",IF(M9<=4,"Средний","Ниже конкурентов")))) | O9: =IF(AND(C9>0,D9>0),(D9-C9)/C9,"") | P9: =IF(AND(C9>0,D9>0),(D9-C9)/D9,"") | Q9: =IF(AND(C9>0,D9>0),D9-C9,"") | R9: =IF(P9="","-",IF(P9<0.1,"Низкая(<10%)",IF(P9<0.2,"Средняя(10-20%)","Хорошая(>20%)"))) | S9: =IF(OR(H9="",C9=""),"-",IF((H9-C9)/H9<0.05,"КРИТИЧНО",IF((H9-C9)/H9<0.15,"УМЕРЕННЫЙ","НИЗКИЙ"))) | U9: =IF(T9>0,T9*D9,"") | V9: =IF(T9>0,T9*Q9,"") | W9: =IF(U9>0,V9/U9,"") | X9: =IF(F9<>"",F9,"") | Y9: =IF(AND(X9<>"",C9>0),(X9-C9)/C9,"") | Z9: =IF(AND(X9<>"",X9>0),(X9-C9)/X9,"") | AA9: =IF(AND(X9<>"",C9>0),X9-C9,"") | AB9: =IF(AND(X9<>"",D9>0),(X9-D9)/D9,"") | AC9: =IF(AND(Z9<>"",P9<>""),(Z9-P9)/ABS(IF(P9=0,1,P9)),"") | AD9: =IF(AND(AA9<>"",Q9<>""),AA9-Q9,"") | AE9: =IF(G9<>"",G9,"") | AF9: =IF(AND(AE9<>"",C9>0),(AE9-C9)/C9,"") | AG9: =IF(AND(AE9<>"",AE9>0),(AE9-C9)/AE9,"") | AH9: =IF(AND(AE9<>"",C9>0),AE9-C9,"") | AI9: =IF(AND(AE9<>"",D9>0),(AE9-D9)/D9,"") | AJ9: =IF(AND(AG9<>"",P9<>""),(AG9-P9)/ABS(IF(P9=0,1,P9)),"") | AK9: =IF(AND(AH9<>"",Q9<>""),AH9-Q9,"") | AL9: =IF(H9<>"",H9,"") | AM9: =IF(AND(AL9<>"",C9>0),(AL9-C9)/C9,"") | AN9: =IF(AND(AL9<>"",AL9>0),(AL9-C9)/AL9,"") | AO9: =IF(AND(AL9<>"",C9>0),AL9-C9,"") | AP9: =IF(AND(AL9<>"",D9>0),(AL9-D9)/D9,"") | AQ9: =IF(AND(AN9<>"",P9<>""),(AN9-P9)/ABS(IF(P9=0,1,P9)),"") | AR9: =IF(AND(AO9<>"",Q9<>""),AO9-Q9,"") | AT9: =IF(AND(AS9>0,C9>0),(AS9-C9)/C9,"") | AU9: =IF(AND(AS9>0,AS9>0),(AS9-C9)/AS9,"") | AV9: =IF(AND(AS9>0,C9>0),AS9-C9,"") | AW9: =IF(AND(AS9>0,D9>0),(AS9-D9)/D9,"") | AX9: =IF(AND(AU9<>"",P9<>""),(AU9-P9)/ABS(IF(P9=0,1,P9)),"") | AY9: =IF(AND(AV9<>"",Q9<>""),AV9-Q9,"") | BA9: =IF(AND(AZ9>0,C9>0),C9/(1-AZ9),"") | BB9: =IF(AND(BA9<>"",C9>0),(BA9-C9)/C9,"") | BC9: =IF(BA9<>"",AZ9,"") | BD9: =IF(AND(BA9<>"",C9>0),BA9-C9,"") | BE9: =IF(AND(BA9<>"",D9>0),(BA9-D9)/D9,"") | BF9: =IF(AND(BC9<>"",P9<>""),(BC9-P9)/ABS(IF(P9=0,1,P9)),"") | BG9: =IF(AND(BD9<>"",Q9<>""),BD9-Q9,"") | BH9: =IF(AND(T9>0,X9<>""),T9*X9,"") | BI9: =IF(AND(T9>0,AA9<>""),T9*AA9,"") | BJ9: =IF(AND(T9>0,AE9<>""),T9*AE9,"") | BK9: =IF(AND(T9>0,AH9<>""),T9*AH9,"") | BL9: =IF(AND(T9>0,AL9<>""),T9*AL9,"") | BM9: =IF(AND(T9>0,AO9<>""),T9*AO9,"") | BN9: =IF(AND(T9>0,AS9>0),T9*AS9,"") | BO9: =IF(AND(T9>0,AV9<>""),T9*AV9,"") | BP9: =IF(AND(T9>0,BA9<>""),T9*BA9,"") | BQ9: =IF(AND(T9>0,BD9<>""),T9*BD9,"") | BR9: =IF(AND(T9>0,V9>0,AA9<>0),V9/AA9-T9,"") | BS9: =IF(AND(BR9<>"",T9>0),BR9/T9,"") | BT9: =IF(AND(T9>0,V9>0,AO9<>0),V9/AO9-T9,"") | BU9: =IF(AND(BT9<>"",T9>0),BT9/T9,"")
A10: ='📊 Исходные данные'!A9 | B10: ='📊 Исходные данные'!B9 | C10: ='📊 Исходные данные'!C9 | D10: ='📊 Исходные данные'!D9 | E10: =IF(OR(D10="",F10=""),"-",IF(D10>F10*1.05,"Выше рынка",IF(D10<F10*0.95,"Ниже рынка","На уровне"))) | F10: =IFERROR(AVERAGE('📊 Исходные данные'!E9,'📊 Исходные данные'!F9,'📊 Исходные данные'!G9,'📊 Исходные данные'!H9,'📊 Исходные данные'!I9,'📊 Исходные данные'!J9,'📊 Исходные данные'!K9),"") | G10: =IFERROR(MEDIAN('📊 Исходные данные'!E9,'📊 Исходные данные'!F9,'📊 Исходные данные'!G9,'📊 Исходные данные'!H9,'📊 Исходные данные'!I9,'📊 Исходные данные'!J9,'📊 Исходные данные'!K9),"") | H10: =IFERROR(MIN('📊 Исходные данные'!E9,'📊 Исходные данные'!F9,'📊 Исходные данные'!G9,'📊 Исходные данные'!H9,'📊 Исходные данные'!I9,'📊 Исходные данные'!J9,'📊 Исходные данные'!K9),"") | I10: =IFERROR(MAX('📊 Исходные данные'!E9,'📊 Исходные данные'!F9,'📊 Исходные данные'!G9,'📊 Исходные данные'!H9,'📊 Исходные данные'!I9,'📊 Исходные данные'!J9,'📊 Исходные данные'!K9),"") | J10: =IF(AND(D10<>"",F10<>""),(D10-F10)/F10,"") | K10: =IF(AND(D10<>"",G10<>""),(D10-G10)/G10,"") | L10: =IF(AND(D10<>"",H10<>""),(D10-H10)/H10,"") | M10: =IFERROR(RANK(D10,('📊 Исходные данные'!E9,'📊 Исходные данные'!F9,'📊 Исходные данные'!G9,'📊 Исходные данные'!H9,'📊 Исходные данные'!I9,'📊 Исходные данные'!J9,'📊 Исходные данные'!K9)),"") | N10: =IF(M10="","-",IF(M10=1,"Дороже всех",IF(M10=2,"2-й по цене",IF(M10<=4,"Средний","Ниже конкурентов")))) | O10: =IF(AND(C10>0,D10>0),(D10-C10)/C10,"") | P10: =IF(AND(C10>0,D10>0),(D10-C10)/D10,"") | Q10: =IF(AND(C10>0,D10>0),D10-C10,"") | R10: =IF(P10="","-",IF(P10<0.1,"Низкая(<10%)",IF(P10<0.2,"Средняя(10-20%)","Хорошая(>20%)"))) | S10: =IF(OR(H10="",C10=""),"-",IF((H10-C10)/H10<0.05,"КРИТИЧНО",IF((H10-C10)/H10<0.15,"УМЕРЕННЫЙ","НИЗКИЙ"))) | U10: =IF(T10>0,T10*D10,"") | V10: =IF(T10>0,T10*Q10,"") | W10: =IF(U10>0,V10/U10,"") | X10: =IF(F10<>"",F10,"") | Y10: =IF(AND(X10<>"",C10>0),(X10-C10)/C10,"") | Z10: =IF(AND(X10<>"",X10>0),(X10-C10)/X10,"") | AA10: =IF(AND(X10<>"",C10>0),X10-C10,"") | AB10: =IF(AND(X10<>"",D10>0),(X10-D10)/D10,"") | AC10: =IF(AND(Z10<>"",P10<>""),(Z10-P10)/ABS(IF(P10=0,1,P10)),"") | AD10: =IF(AND(AA10<>"",Q10<>""),AA10-Q10,"") | AE10: =IF(G10<>"",G10,"") | AF10: =IF(AND(AE10<>"",C10>0),(AE10-C10)/C10,"") | AG10: =IF(AND(AE10<>"",AE10>0),(AE10-C10)/AE10,"") | AH10: =IF(AND(AE10<>"",C10>0),AE10-C10,"") | AI10: =IF(AND(AE10<>"",D10>0),(AE10-D10)/D10,"") | AJ10: =IF(AND(AG10<>"",P10<>""),(AG10-P10)/ABS(IF(P10=0,1,P10)),"") | AK10: =IF(AND(AH10<>"",Q10<>""),AH10-Q10,"") | AL10: =IF(H10<>"",H10,"") | AM10: =IF(AND(AL10<>"",C10>0),(AL10-C10)/C10,"") | AN10: =IF(AND(AL10<>"",AL10>0),(AL10-C10)/AL10,"") | AO10: =IF(AND(AL10<>"",C10>0),AL10-C10,"") | AP10: =IF(AND(AL10<>"",D10>0),(AL10-D10)/D10,"") | AQ10: =IF(AND(AN10<>"",P10<>""),(AN10-P10)/ABS(IF(P10=0,1,P10)),"") | AR10: =IF(AND(AO10<>"",Q10<>""),AO10-Q10,"") | AT10: =IF(AND(AS10>0,C10>0),(AS10-C10)/C10,"") | AU10: =IF(AND(AS10>0,AS10>0),(AS10-C10)/AS10,"") | AV10: =IF(AND(AS10>0,C10>0),AS10-C10,"") | AW10: =IF(AND(AS10>0,D10>0),(AS10-D10)/D10,"") | AX10: =IF(AND(AU10<>"",P10<>""),(AU10-P10)/ABS(IF(P10=0,1,P10)),"") | AY10: =IF(AND(AV10<>"",Q10<>""),AV10-Q10,"") | BA10: =IF(AND(AZ10>0,C10>0),C10/(1-AZ10),"") | BB10: =IF(AND(BA10<>"",C10>0),(BA10-C10)/C10,"") | BC10: =IF(BA10<>"",AZ10,"") | BD10: =IF(AND(BA10<>"",C10>0),BA10-C10,"") | BE10: =IF(AND(BA10<>"",D10>0),(BA10-D10)/D10,"") | BF10: =IF(AND(BC10<>"",P10<>""),(BC10-P10)/ABS(IF(P10=0,1,P10)),"") | BG10: =IF(AND(BD10<>"",Q10<>""),BD10-Q10,"") | BH10: =IF(AND(T10>0,X10<>""),T10*X10,"") | BI10: =IF(AND(T10>0,AA10<>""),T10*AA10,"") | BJ10: =IF(AND(T10>0,AE10<>""),T10*AE10,"") | BK10: =IF(AND(T10>0,AH10<>""),T10*AH10,"") | BL10: =IF(AND(T10>0,AL10<>""),T10*AL10,"") | BM10: =IF(AND(T10>0,AO10<>""),T10*AO10,"") | BN10: =IF(AND(T10>0,AS10>0),T10*AS10,"") | BO10: =IF(AND(T10>0,AV10<>""),T10*AV10,"") | BP10: =IF(AND(T10>0,BA10<>""),T10*BA10,"") | BQ10: =IF(AND(T10>0,BD10<>""),T10*BD10,"") | BR10: =IF(AND(T10>0,V10>0,AA10<>0),V10/AA10-T10,"") | BS10: =IF(AND(BR10<>"",T10>0),BR10/T10,"") | BT10: =IF(AND(T10>0,V10>0,AO10<>0),V10/AO10-T10,"") | BU10: =IF(AND(BT10<>"",T10>0),BT10/T10,"")
A11: ='📊 Исходные данные'!A10 | B11: ='📊 Исходные данные'!B10 | C11: ='📊 Исходные данные'!C10 | D11: ='📊 Исходные данные'!D10 | E11: =IF(OR(D11="",F11=""),"-",IF(D11>F11*1.05,"Выше рынка",IF(D11<F11*0.95,"Ниже рынка","На уровне"))) | F11: =IFERROR(AVERAGE('📊 Исходные данные'!E10,'📊 Исходные данные'!F10,'📊 Исходные данные'!G10,'📊 Исходные данные'!H10,'📊 Исходные данные'!I10,'📊 Исходные данные'!J10,'📊 Исходные данные'!K10),"") | G11: =IFERROR(MEDIAN('📊 Исходные данные'!E10,'📊 Исходные данные'!F10,'📊 Исходные данные'!G10,'📊 Исходные данные'!H10,'📊 Исходные данные'!I10,'📊 Исходные данные'!J10,'📊 Исходные данные'!K10),"") | H11: =IFERROR(MIN('📊 Исходные данные'!E10,'📊 Исходные данные'!F10,'📊 Исходные данные'!G10,'📊 Исходные данные'!H10,'📊 Исходные данные'!I10,'📊 Исходные данные'!J10,'📊 Исходные данные'!K10),"") | I11: =IFERROR(MAX('📊 Исходные данные'!E10,'📊 Исходные данные'!F10,'📊 Исходные данные'!G10,'📊 Исходные данные'!H10,'📊 Исходные данные'!I10,'📊 Исходные данные'!J10,'📊 Исходные данные'!K10),"") | J11: =IF(AND(D11<>"",F11<>""),(D11-F11)/F11,"") | K11: =IF(AND(D11<>"",G11<>""),(D11-G11)/G11,"") | L11: =IF(AND(D11<>"",H11<>""),(D11-H11)/H11,"") | M11: =IFERROR(RANK(D11,('📊 Исходные данные'!E10,'📊 Исходные данные'!F10,'📊 Исходные данные'!G10,'📊 Исходные данные'!H10,'📊 Исходные данные'!I10,'📊 Исходные данные'!J10,'📊 Исходные данные'!K10)),"") | N11: =IF(M11="","-",IF(M11=1,"Дороже всех",IF(M11=2,"2-й по цене",IF(M11<=4,"Средний","Ниже конкурентов")))) | O11: =IF(AND(C11>0,D11>0),(D11-C11)/C11,"") | P11: =IF(AND(C11>0,D11>0),(D11-C11)/D11,"") | Q11: =IF(AND(C11>0,D11>0),D11-C11,"") | R11: =IF(P11="","-",IF(P11<0.1,"Низкая(<10%)",IF(P11<0.2,"Средняя(10-20%)","Хорошая(>20%)"))) | S11: =IF(OR(H11="",C11=""),"-",IF((H11-C11)/H11<0.05,"КРИТИЧНО",IF((H11-C11)/H11<0.15,"УМЕРЕННЫЙ","НИЗКИЙ"))) | U11: =IF(T11>0,T11*D11,"") | V11: =IF(T11>0,T11*Q11,"") | W11: =IF(U11>0,V11/U11,"") | X11: =IF(F11<>"",F11,"") | Y11: =IF(AND(X11<>"",C11>0),(X11-C11)/C11,"") | Z11: =IF(AND(X11<>"",X11>0),(X11-C11)/X11,"") | AA11: =IF(AND(X11<>"",C11>0),X11-C11,"") | AB11: =IF(AND(X11<>"",D11>0),(X11-D11)/D11,"") | AC11: =IF(AND(Z11<>"",P11<>""),(Z11-P11)/ABS(IF(P11=0,1,P11)),"") | AD11: =IF(AND(AA11<>"",Q11<>""),AA11-Q11,"") | AE11: =IF(G11<>"",G11,"") | AF11: =IF(AND(AE11<>"",C11>0),(AE11-C11)/C11,"") | AG11: =IF(AND(AE11<>"",AE11>0),(AE11-C11)/AE11,"") | AH11: =IF(AND(AE11<>"",C11>0),AE11-C11,"") | AI11: =IF(AND(AE11<>"",D11>0),(AE11-D11)/D11,"") | AJ11: =IF(AND(AG11<>"",P11<>""),(AG11-P11)/ABS(IF(P11=0,1,P11)),"") | AK11: =IF(AND(AH11<>"",Q11<>""),AH11-Q11,"") | AL11: =IF(H11<>"",H11,"") | AM11: =IF(AND(AL11<>"",C11>0),(AL11-C11)/C11,"") | AN11: =IF(AND(AL11<>"",AL11>0),(AL11-C11)/AL11,"") | AO11: =IF(AND(AL11<>"",C11>0),AL11-C11,"") | AP11: =IF(AND(AL11<>"",D11>0),(AL11-D11)/D11,"") | AQ11: =IF(AND(AN11<>"",P11<>""),(AN11-P11)/ABS(IF(P11=0,1,P11)),"") | AR11: =IF(AND(AO11<>"",Q11<>""),AO11-Q11,"") | AT11: =IF(AND(AS11>0,C11>0),(AS11-C11)/C11,"") | AU11: =IF(AND(AS11>0,AS11>0),(AS11-C11)/AS11,"") | AV11: =IF(AND(AS11>0,C11>0),AS11-C11,"") | AW11: =IF(AND(AS11>0,D11>0),(AS11-D11)/D11,"") | AX11: =IF(AND(AU11<>"",P11<>""),(AU11-P11)/ABS(IF(P11=0,1,P11)),"") | AY11: =IF(AND(AV11<>"",Q11<>""),AV11-Q11,"") | BA11: =IF(AND(AZ11>0,C11>0),C11/(1-AZ11),"") | BB11: =IF(AND(BA11<>"",C11>0),(BA11-C11)/C11,"") | BC11: =IF(BA11<>"",AZ11,"") | BD11: =IF(AND(BA11<>"",C11>0),BA11-C11,"") | BE11: =IF(AND(BA11<>"",D11>0),(BA11-D11)/D11,"") | BF11: =IF(AND(BC11<>"",P11<>""),(BC11-P11)/ABS(IF(P11=0,1,P11)),"") | BG11: =IF(AND(BD11<>"",Q11<>""),BD11-Q11,"") | BH11: =IF(AND(T11>0,X11<>""),T11*X11,"") | BI11: =IF(AND(T11>0,AA11<>""),T11*AA11,"") | BJ11: =IF(AND(T11>0,AE11<>""),T11*AE11,"") | BK11: =IF(AND(T11>0,AH11<>""),T11*AH11,"") | BL11: =IF(AND(T11>0,AL11<>""),T11*AL11,"") | BM11: =IF(AND(T11>0,AO11<>""),T11*AO11,"") | BN11: =IF(AND(T11>0,AS11>0),T11*AS11,"") | BO11: =IF(AND(T11>0,AV11<>""),T11*AV11,"") | BP11: =IF(AND(T11>0,BA11<>""),T11*BA11,"") | BQ11: =IF(AND(T11>0,BD11<>""),T11*BD11,"") | BR11: =IF(AND(T11>0,V11>0,AA11<>0),V11/AA11-T11,"") | BS11: =IF(AND(BR11<>"",T11>0),BR11/T11,"") | BT11: =IF(AND(T11>0,V11>0,AO11<>0),V11/AO11-T11,"") | BU11: =IF(AND(BT11<>"",T11>0),BT11/T11,"")
A12: ='📊 Исходные данные'!A11 | B12: ='📊 Исходные данные'!B11 | C12: ='📊 Исходные данные'!C11 | D12: ='📊 Исходные данные'!D11 | E12: =IF(OR(D12="",F12=""),"-",IF(D12>F12*1.05,"Выше рынка",IF(D12<F12*0.95,"Ниже рынка","На уровне"))) | F12: =IFERROR(AVERAGE('📊 Исходные данные'!E11,'📊 Исходные данные'!F11,'📊 Исходные данные'!G11,'📊 Исходные данные'!H11,'📊 Исходные данные'!I11,'📊 Исходные данные'!J11,'📊 Исходные данные'!K11),"") | G12: =IFERROR(MEDIAN('📊 Исходные данные'!E11,'📊 Исходные данные'!F11,'📊 Исходные данные'!G11,'📊 Исходные данные'!H11,'📊 Исходные данные'!I11,'📊 Исходные данные'!J11,'📊 Исходные данные'!K11),"") | H12: =IFERROR(MIN('📊 Исходные данные'!E11,'📊 Исходные данные'!F11,'📊 Исходные данные'!G11,'📊 Исходные данные'!H11,'📊 Исходные данные'!I11,'📊 Исходные данные'!J11,'📊 Исходные данные'!K11),"") | I12: =IFERROR(MAX('📊 Исходные данные'!E11,'📊 Исходные данные'!F11,'📊 Исходные данные'!G11,'📊 Исходные данные'!H11,'📊 Исходные данные'!I11,'📊 Исходные данные'!J11,'📊 Исходные данные'!K11),"") | J12: =IF(AND(D12<>"",F12<>""),(D12-F12)/F12,"") | K12: =IF(AND(D12<>"",G12<>""),(D12-G12)/G12,"") | L12: =IF(AND(D12<>"",H12<>""),(D12-H12)/H12,"") | M12: =IFERROR(RANK(D12,('📊 Исходные данные'!E11,'📊 Исходные данные'!F11,'📊 Исходные данные'!G11,'📊 Исходные данные'!H11,'📊 Исходные данные'!I11,'📊 Исходные данные'!J11,'📊 Исходные данные'!K11)),"") | N12: =IF(M12="","-",IF(M12=1,"Дороже всех",IF(M12=2,"2-й по цене",IF(M12<=4,"Средний","Ниже конкурентов")))) | O12: =IF(AND(C12>0,D12>0),(D12-C12)/C12,"") | P12: =IF(AND(C12>0,D12>0),(D12-C12)/D12,"") | Q12: =IF(AND(C12>0,D12>0),D12-C12,"") | R12: =IF(P12="","-",IF(P12<0.1,"Низкая(<10%)",IF(P12<0.2,"Средняя(10-20%)","Хорошая(>20%)"))) | S12: =IF(OR(H12="",C12=""),"-",IF((H12-C12)/H12<0.05,"КРИТИЧНО",IF((H12-C12)/H12<0.15,"УМЕРЕННЫЙ","НИЗКИЙ"))) | U12: =IF(T12>0,T12*D12,"") | V12: =IF(T12>0,T12*Q12,"") | W12: =IF(U12>0,V12/U12,"") | X12: =IF(F12<>"",F12,"") | Y12: =IF(AND(X12<>"",C12>0),(X12-C12)/C12,"") | Z12: =IF(AND(X12<>"",X12>0),(X12-C12)/X12,"") | AA12: =IF(AND(X12<>"",C12>0),X12-C12,"") | AB12: =IF(AND(X12<>"",D12>0),(X12-D12)/D12,"") | AC12: =IF(AND(Z12<>"",P12<>""),(Z12-P12)/ABS(IF(P12=0,1,P12)),"") | AD12: =IF(AND(AA12<>"",Q12<>""),AA12-Q12,"") | AE12: =IF(G12<>"",G12,"") | AF12: =IF(AND(AE12<>"",C12>0),(AE12-C12)/C12,"") | AG12: =IF(AND(AE12<>"",AE12>0),(AE12-C12)/AE12,"") | AH12: =IF(AND(AE12<>"",C12>0),AE12-C12,"") | AI12: =IF(AND(AE12<>"",D12>0),(AE12-D12)/D12,"") | AJ12: =IF(AND(AG12<>"",P12<>""),(AG12-P12)/ABS(IF(P12=0,1,P12)),"") | AK12: =IF(AND(AH12<>"",Q12<>""),AH12-Q12,"") | AL12: =IF(H12<>"",H12,"") | AM12: =IF(AND(AL12<>"",C12>0),(AL12-C12)/C12,"") | AN12: =IF(AND(AL12<>"",AL12>0),(AL12-C12)/AL12,"") | AO12: =IF(AND(AL12<>"",C12>0),AL12-C12,"") | AP12: =IF(AND(AL12<>"",D12>0),(AL12-D12)/D12,"") | AQ12: =IF(AND(AN12<>"",P12<>""),(AN12-P12)/ABS(IF(P12=0,1,P12)),"") | AR12: =IF(AND(AO12<>"",Q12<>""),AO12-Q12,"") | AT12: =IF(AND(AS12>0,C12>0),(AS12-C12)/C12,"") | AU12: =IF(AND(AS12>0,AS12>0),(AS12-C12)/AS12,"") | AV12: =IF(AND(AS12>0,C12>0),AS12-C12,"") | AW12: =IF(AND(AS12>0,D12>0),(AS12-D12)/D12,"") | AX12: =IF(AND(AU12<>"",P12<>""),(AU12-P12)/ABS(IF(P12=0,1,P12)),"") | AY12: =IF(AND(AV12<>"",Q12<>""),AV12-Q12,"") | BA12: =IF(AND(AZ12>0,C12>0),C12/(1-AZ12),"") | BB12: =IF(AND(BA12<>"",C12>0),(BA12-C12)/C12,"") | BC12: =IF(BA12<>"",AZ12,"") | BD12: =IF(AND(BA12<>"",C12>0),BA12-C12,"") | BE12: =IF(AND(BA12<>"",D12>0),(BA12-D12)/D12,"") | BF12: =IF(AND(BC12<>"",P12<>""),(BC12-P12)/ABS(IF(P12=0,1,P12)),"") | BG12: =IF(AND(BD12<>"",Q12<>""),BD12-Q12,"") | BH12: =IF(AND(T12>0,X12<>""),T12*X12,"") | BI12: =IF(AND(T12>0,AA12<>""),T12*AA12,"") | BJ12: =IF(AND(T12>0,AE12<>""),T12*AE12,"") | BK12: =IF(AND(T12>0,AH12<>""),T12*AH12,"") | BL12: =IF(AND(T12>0,AL12<>""),T12*AL12,"") | BM12: =IF(AND(T12>0,AO12<>""),T12*AO12,"") | BN12: =IF(AND(T12>0,AS12>0),T12*AS12,"") | BO12: =IF(AND(T12>0,AV12<>""),T12*AV12,"") | BP12: =IF(AND(T12>0,BA12<>""),T12*BA12,"") | BQ12: =IF(AND(T12>0,BD12<>""),T12*BD12,"") | BR12: =IF(AND(T12>0,V12>0,AA12<>0),V12/AA12-T12,"") | BS12: =IF(AND(BR12<>"",T12>0),BR12/T12,"") | BT12: =IF(AND(T12>0,V12>0,AO12<>0),V12/AO12-T12,"") | BU12: =IF(AND(BT12<>"",T12>0),BT12/T12,"")
A13: ='📊 Исходные данные'!A12 | B13: ='📊 Исходные данные'!B12 | C13: ='📊 Исходные данные'!C12 | D13: ='📊 Исходные данные'!D12 | E13: =IF(OR(D13="",F13=""),"-",IF(D13>F13*1.05,"Выше рынка",IF(D13<F13*0.95,"Ниже рынка","На уровне"))) | F13: =IFERROR(AVERAGE('📊 Исходные данные'!E12,'📊 Исходные данные'!F12,'📊 Исходные данные'!G12,'📊 Исходные данные'!H12,'📊 Исходные данные'!I12,'📊 Исходные данные'!J12,'📊 Исходные данные'!K12),"") | G13: =IFERROR(MEDIAN('📊 Исходные данные'!E12,'📊 Исходные данные'!F12,'📊 Исходные данные'!G12,'📊 Исходные данные'!H12,'📊 Исходные данные'!I12,'📊 Исходные данные'!J12,'📊 Исходные данные'!K12),"") | H13: =IFERROR(MIN('📊 Исходные данные'!E12,'📊 Исходные данные'!F12,'📊 Исходные данные'!G12,'📊 Исходные данные'!H12,'📊 Исходные данные'!I12,'📊 Исходные данные'!J12,'📊 Исходные данные'!K12),"") | I13: =IFERROR(MAX('📊 Исходные данные'!E12,'📊 Исходные данные'!F12,'📊 Исходные данные'!G12,'📊 Исходные данные'!H12,'📊 Исходные данные'!I12,'📊 Исходные данные'!J12,'📊 Исходные данные'!K12),"") | J13: =IF(AND(D13<>"",F13<>""),(D13-F13)/F13,"") | K13: =IF(AND(D13<>"",G13<>""),(D13-G13)/G13,"") | L13: =IF(AND(D13<>"",H13<>""),(D13-H13)/H13,"") | M13: =IFERROR(RANK(D13,('📊 Исходные данные'!E12,'📊 Исходные данные'!F12,'📊 Исходные данные'!G12,'📊 Исходные данные'!H12,'📊 Исходные данные'!I12,'📊 Исходные данные'!J12,'📊 Исходные данные'!K12)),"") | N13: =IF(M13="","-",IF(M13=1,"Дороже всех",IF(M13=2,"2-й по цене",IF(M13<=4,"Средний","Ниже конкурентов")))) | O13: =IF(AND(C13>0,D13>0),(D13-C13)/C13,"") | P13: =IF(AND(C13>0,D13>0),(D13-C13)/D13,"") | Q13: =IF(AND(C13>0,D13>0),D13-C13,"") | R13: =IF(P13="","-",IF(P13<0.1,"Низкая(<10%)",IF(P13<0.2,"Средняя(10-20%)","Хорошая(>20%)"))) | S13: =IF(OR(H13="",C13=""),"-",IF((H13-C13)/H13<0.05,"КРИТИЧНО",IF((H13-C13)/H13<0.15,"УМЕРЕННЫЙ","НИЗКИЙ"))) | U13: =IF(T13>0,T13*D13,"") | V13: =IF(T13>0,T13*Q13,"") | W13: =IF(U13>0,V13/U13,"") | X13: =IF(F13<>"",F13,"") | Y13: =IF(AND(X13<>"",C13>0),(X13-C13)/C13,"") | Z13: =IF(AND(X13<>"",X13>0),(X13-C13)/X13,"") | AA13: =IF(AND(X13<>"",C13>0),X13-C13,"") | AB13: =IF(AND(X13<>"",D13>0),(X13-D13)/D13,"") | AC13: =IF(AND(Z13<>"",P13<>""),(Z13-P13)/ABS(IF(P13=0,1,P13)),"") | AD13: =IF(AND(AA13<>"",Q13<>""),AA13-Q13,"") | AE13: =IF(G13<>"",G13,"") | AF13: =IF(AND(AE13<>"",C13>0),(AE13-C13)/C13,"") | AG13: =IF(AND(AE13<>"",AE13>0),(AE13-C13)/AE13,"") | AH13: =IF(AND(AE13<>"",C13>0),AE13-C13,"") | AI13: =IF(AND(AE13<>"",D13>0),(AE13-D13)/D13,"") | AJ13: =IF(AND(AG13<>"",P13<>""),(AG13-P13)/ABS(IF(P13=0,1,P13)),"") | AK13: =IF(AND(AH13<>"",Q13<>""),AH13-Q13,"") | AL13: =IF(H13<>"",H13,"") | AM13: =IF(AND(AL13<>"",C13>0),(AL13-C13)/C13,"") | AN13: =IF(AND(AL13<>"",AL13>0),(AL13-C13)/AL13,"") | AO13: =IF(AND(AL13<>"",C13>0),AL13-C13,"") | AP13: =IF(AND(AL13<>"",D13>0),(AL13-D13)/D13,"") | AQ13: =IF(AND(AN13<>"",P13<>""),(AN13-P13)/ABS(IF(P13=0,1,P13)),"") | AR13: =IF(AND(AO13<>"",Q13<>""),AO13-Q13,"") | AT13: =IF(AND(AS13>0,C13>0),(AS13-C13)/C13,"") | AU13: =IF(AND(AS13>0,AS13>0),(AS13-C13)/AS13,"") | AV13: =IF(AND(AS13>0,C13>0),AS13-C13,"") | AW13: =IF(AND(AS13>0,D13>0),(AS13-D13)/D13,"") | AX13: =IF(AND(AU13<>"",P13<>""),(AU13-P13)/ABS(IF(P13=0,1,P13)),"") | AY13: =IF(AND(AV13<>"",Q13<>""),AV13-Q13,"") | BA13: =IF(AND(AZ13>0,C13>0),C13/(1-AZ13),"") | BB13: =IF(AND(BA13<>"",C13>0),(BA13-C13)/C13,"") | BC13: =IF(BA13<>"",AZ13,"") | BD13: =IF(AND(BA13<>"",C13>0),BA13-C13,"") | BE13: =IF(AND(BA13<>"",D13>0),(BA13-D13)/D13,"") | BF13: =IF(AND(BC13<>"",P13<>""),(BC13-P13)/ABS(IF(P13=0,1,P13)),"") | BG13: =IF(AND(BD13<>"",Q13<>""),BD13-Q13,"") | BH13: =IF(AND(T13>0,X13<>""),T13*X13,"") | BI13: =IF(AND(T13>0,AA13<>""),T13*AA13,"") | BJ13: =IF(AND(T13>0,AE13<>""),T13*AE13,"") | BK13: =IF(AND(T13>0,AH13<>""),T13*AH13,"") | BL13: =IF(AND(T13>0,AL13<>""),T13*AL13,"") | BM13: =IF(AND(T13>0,AO13<>""),T13*AO13,"") | BN13: =IF(AND(T13>0,AS13>0),T13*AS13,"") | BO13: =IF(AND(T13>0,AV13<>""),T13*AV13,"") | BP13: =IF(AND(T13>0,BA13<>""),T13*BA13,"") | BQ13: =IF(AND(T13>0,BD13<>""),T13*BD13,"") | BR13: =IF(AND(T13>0,V13>0,AA13<>0),V13/AA13-T13,"") | BS13: =IF(AND(BR13<>"",T13>0),BR13/T13,"") | BT13: =IF(AND(T13>0,V13>0,AO13<>0),V13/AO13-T13,"") | BU13: =IF(AND(BT13<>"",T13>0),BT13/T13,"")
A14: ='📊 Исходные данные'!A13 | B14: ='📊 Исходные данные'!B13 | C14: ='📊 Исходные данные'!C13 | D14: ='📊 Исходные данные'!D13 | E14: =IF(OR(D14="",F14=""),"-",IF(D14>F14*1.05,"Выше рынка",IF(D14<F14*0.95,"Ниже рынка","На уровне"))) | F14: =IFERROR(AVERAGE('📊 Исходные данные'!E13,'📊 Исходные данные'!F13,'📊 Исходные данные'!G13,'📊 Исходные данные'!H13,'📊 Исходные данные'!I13,'📊 Исходные данные'!J13,'📊 Исходные данные'!K13),"") | G14: =IFERROR(MEDIAN('📊 Исходные данные'!E13,'📊 Исходные данные'!F13,'📊 Исходные данные'!G13,'📊 Исходные данные'!H13,'📊 Исходные данные'!I13,'📊 Исходные данные'!J13,'📊 Исходные данные'!K13),"") | H14: =IFERROR(MIN('📊 Исходные данные'!E13,'📊 Исходные данные'!F13,'📊 Исходные данные'!G13,'📊 Исходные данные'!H13,'📊 Исходные данные'!I13,'📊 Исходные данные'!J13,'📊 Исходные данные'!K13),"") | I14: =IFERROR(MAX('📊 Исходные данные'!E13,'📊 Исходные данные'!F13,'📊 Исходные данные'!G13,'📊 Исходные данные'!H13,'📊 Исходные данные'!I13,'📊 Исходные данные'!J13,'📊 Исходные данные'!K13),"") | J14: =IF(AND(D14<>"",F14<>""),(D14-F14)/F14,"") | K14: =IF(AND(D14<>"",G14<>""),(D14-G14)/G14,"") | L14: =IF(AND(D14<>"",H14<>""),(D14-H14)/H14,"") | M14: =IFERROR(RANK(D14,('📊 Исходные данные'!E13,'📊 Исходные данные'!F13,'📊 Исходные данные'!G13,'📊 Исходные данные'!H13,'📊 Исходные данные'!I13,'📊 Исходные данные'!J13,'📊 Исходные данные'!K13)),"") | N14: =IF(M14="","-",IF(M14=1,"Дороже всех",IF(M14=2,"2-й по цене",IF(M14<=4,"Средний","Ниже конкурентов")))) | O14: =IF(AND(C14>0,D14>0),(D14-C14)/C14,"") | P14: =IF(AND(C14>0,D14>0),(D14-C14)/D14,"") | Q14: =IF(AND(C14>0,D14>0),D14-C14,"") | R14: =IF(P14="","-",IF(P14<0.1,"Низкая(<10%)",IF(P14<0.2,"Средняя(10-20%)","Хорошая(>20%)"))) | S14: =IF(OR(H14="",C14=""),"-",IF((H14-C14)/H14<0.05,"КРИТИЧНО",IF((H14-C14)/H14<0.15,"УМЕРЕННЫЙ","НИЗКИЙ"))) | U14: =IF(T14>0,T14*D14,"") | V14: =IF(T14>0,T14*Q14,"") | W14: =IF(U14>0,V14/U14,"") | X14: =IF(F14<>"",F14,"") | Y14: =IF(AND(X14<>"",C14>0),(X14-C14)/C14,"") | Z14: =IF(AND(X14<>"",X14>0),(X14-C14)/X14,"") | AA14: =IF(AND(X14<>"",C14>0),X14-C14,"") | AB14: =IF(AND(X14<>"",D14>0),(X14-D14)/D14,"") | AC14: =IF(AND(Z14<>"",P14<>""),(Z14-P14)/ABS(IF(P14=0,1,P14)),"") | AD14: =IF(AND(AA14<>"",Q14<>""),AA14-Q14,"") | AE14: =IF(G14<>"",G14,"") | AF14: =IF(AND(AE14<>"",C14>0),(AE14-C14)/C14,"") | AG14: =IF(AND(AE14<>"",AE14>0),(AE14-C14)/AE14,"") | AH14: =IF(AND(AE14<>"",C14>0),AE14-C14,"") | AI14: =IF(AND(AE14<>"",D14>0),(AE14-D14)/D14,"") | AJ14: =IF(AND(AG14<>"",P14<>""),(AG14-P14)/ABS(IF(P14=0,1,P14)),"") | AK14: =IF(AND(AH14<>"",Q14<>""),AH14-Q14,"") | AL14: =IF(H14<>"",H14,"") | AM14: =IF(AND(AL14<>"",C14>0),(AL14-C14)/C14,"") | AN14: =IF(AND(AL14<>"",AL14>0),(AL14-C14)/AL14,"") | AO14: =IF(AND(AL14<>"",C14>0),AL14-C14,"") | AP14: =IF(AND(AL14<>"",D14>0),(AL14-D14)/D14,"") | AQ14: =IF(AND(AN14<>"",P14<>""),(AN14-P14)/ABS(IF(P14=0,1,P14)),"") | AR14: =IF(AND(AO14<>"",Q14<>""),AO14-Q14,"") | AT14: =IF(AND(AS14>0,C14>0),(AS14-C14)/C14,"") | AU14: =IF(AND(AS14>0,AS14>0),(AS14-C14)/AS14,"") | AV14: =IF(AND(AS14>0,C14>0),AS14-C14,"") | AW14: =IF(AND(AS14>0,D14>0),(AS14-D14)/D14,"") | AX14: =IF(AND(AU14<>"",P14<>""),(AU14-P14)/ABS(IF(P14=0,1,P14)),"") | AY14: =IF(AND(AV14<>"",Q14<>""),AV14-Q14,"") | BA14: =IF(AND(AZ14>0,C14>0),C14/(1-AZ14),"") | BB14: =IF(AND(BA14<>"",C14>0),(BA14-C14)/C14,"") | BC14: =IF(BA14<>"",AZ14,"") | BD14: =IF(AND(BA14<>"",C14>0),BA14-C14,"") | BE14: =IF(AND(BA14<>"",D14>0),(BA14-D14)/D14,"") | BF14: =IF(AND(BC14<>"",P14<>""),(BC14-P14)/ABS(IF(P14=0,1,P14)),"") | BG14: =IF(AND(BD14<>"",Q14<>""),BD14-Q14,"") | BH14: =IF(AND(T14>0,X14<>""),T14*X14,"") | BI14: =IF(AND(T14>0,AA14<>""),T14*AA14,"") | BJ14: =IF(AND(T14>0,AE14<>""),T14*AE14,"") | BK14: =IF(AND(T14>0,AH14<>""),T14*AH14,"") | BL14: =IF(AND(T14>0,AL14<>""),T14*AL14,"") | BM14: =IF(AND(T14>0,AO14<>""),T14*AO14,"") | BN14: =IF(AND(T14>0,AS14>0),T14*AS14,"") | BO14: =IF(AND(T14>0,AV14<>""),T14*AV14,"") | BP14: =IF(AND(T14>0,BA14<>""),T14*BA14,"") | BQ14: =IF(AND(T14>0,BD14<>""),T14*BD14,"") | BR14: =IF(AND(T14>0,V14>0,AA14<>0),V14/AA14-T14,"") | BS14: =IF(AND(BR14<>"",T14>0),BR14/T14,"") | BT14: =IF(AND(T14>0,V14>0,AO14<>0),V14/AO14-T14,"") | BU14: =IF(AND(BT14<>"",T14>0),BT14/T14,"")
