Workbook

Sheet Инструкция
A1: Excel-калькулятор цен сети «Зеленое Яблоко»
A3: Назначение: управление ценой, маржой и валовой прибылью по топовым позициям, сравнение с рынком и сценарное моделирование.
A5: Как пользоваться:
A6: 1. На листе «Исходные данные» находятся товары, штрихкоды, закупочная и розничная цена ЗЯ, цены конкурентов.
A7: Данные загружаются из исходного файла или дополняются вручную.
A8: 2. На листе «Продажи» вручную заполняются текущие продажи в Зеленом Яблоке по штрихкоду: количество, выручка, валовая прибыль.
A9: 3. Лист «Расчеты» автоматически формирует аналитику по ценам, марже, валовой прибыли и всем сценариям.
A10: 4. Лист «Dashboard» отображает KPI, количество позиций выше/ниже рынка, суммарную текущую и прогнозную валовую прибыль.
A11: 5. Лист «Сценарный анализ» содержит сводный анализ по всем позициям и сценариям, а также рекомендации.
A13: Поля ручного ввода:
A14: - Лист «Исходные данные»: все ценовые поля (если их нужно скорректировать), штрихкоды и наименование.
A15: - Лист «Продажи»: Количество_продаж, Выручка, Валовая_прибыль по каждому штрихкоду.
... A22: Важно: не изменяйте формулы в расчётных столбцах. Добавляйте новые позиции через вставку строк внутрь таблиц.

Sheet Исходные данные
A1: Наименование | B1: Штрихкод | C1: Закупочная_цена_ЗЯ | D1: Розничная_цена_ЗЯ | E1: Цена_7_Континент | F1: Цена_Европейский | G1: Цена_Тропики | H1: Цена_Мята | I1: Цена_Отличный | J1: Цена_Оптовик_Молоток | K1: Цена_Оптовик_Редукторный
A2: Белизна гипохлорид 1л | B2: 4665272570017 | C2: 29 | D2: 39 | F2: 55 | I2: 52 | J2: 41
A3: Гель белизна Санфор 3в1 700мл | B3: 4602984001637 | C3: 87.83 | D3: 119 (159) | H3: 131 | J3: 110
A4: Гель Ласка 1л для Черного Эффект восстановления | B4: 9000101409321 | C4: 236.18 | D4: 339 | F4: 349 | H4: 301 | J4: 265
A5: Кондиционер ABC для белья 1440мл Элегантная Орхидея | B5: 8690511000983 | C5: 235 | D5: 289 | F5: 285 | H5: 288 | J5: 240 | K5: 230
A6: Порошок ABC авт 3кг Лимон | B6: 8690511171614 | C6: 255 | D6: 385 | F6: 356 | H6: 394 | I6: 329 | K6: 299
A7: Порошок Ариэль авт 3кг Колор | B7: 5413149333437 | C7: 496.63 | D7: 599 | E7: 673 | H7: 540 | J7: 490
A8: Отбеливатель Бос плюс Макс 500г | B8: 4600905000332 | C8: 127 | D8: 179 | I8: 191
A9: Средство AOS для посуды 450г Лимон | B9: 4604049012305 | C9: 67.94 | D9: 85 | E9: 107 | H9: 85 | I9: 88 | J9: 80 | K9: 71
A10: Средство AOS для посуды 900г Лимон | B10: 4604049095476 | C10: 131.78 | D10: 199 | H10: 169 | I10: 179 | J10: 140 | K10: 138
A11: Средство Грасс Azelit Антижир для кухни спрей 600мл | B11: 4607072197537 | C11: 116.07 | D11: 159 | E11: 157 | H11: 157 | J11: 125
A12: Средство Доместос 1,5л Ультра блеск | B12: 8714100797525 | C12: 160.16 | D12: 249
A13: Средство Доместос 500мл Ультра блеск | B13: 8714100707890 | C13: 77.02 | D13: 139 | H13: 124 | J13: 105
A14: Кассеты для бритья Жиллетт Фьюжн 4шт | B14: 7702018874460
A15: Зубная паста Сплат Профессионал 100г Отбеливание плюс | B15: 4603014023704
A16: Мыло жидкое Грасс Milana 1000мл Perfume | B16: 4670113604165
A17: Салфетки влажные Мануоки детские 80шт | B17: 4620174812764
A18: Полотенца бумажные Папия Декор 3 слоя 2 рулона | B18: 4604857001782 | C18: 99.19 | D18: 129 (145) | F18: 134 | H18: 127 | I18: 139 | J18: 100
A19: Туалетная бумага Папия 3сл 4рул белая | B19: 8690536023936
A20: Полотенца бумажные Zemma 2сл 2рул | B20: 4670199857349 | C20: 77 | D20: 99 (125)
A21: Туалетная бумага Zemma Плюс 2сл 4шт Белая | B21: 4605331003308 | C21: 77 | D21: 99 (125) | H21: 95 | J21: 90
A23: Крупа Гречневая (ядрица) Первый сорт 1кг | B23: 2057030071836 | C23: 48 | D23: 59 | E23: 75 | I23: 61 | J23: 60
A24: Крупа Рисовая (рис шлифованный) 1кг | B24: 2058077055810 | C24: 60 | D24: 79 | E24: 87 | I24: 91 | J24: 80 | K24: 80
A25: Крупа Увелка Гречневая Экстра 800г | B25: 4607016240893 | C25: 71.35 | D25: 89 | E25: 99 | F25: 94 | G25: 100 | H25: 89 | I25: 91 | J25: 90
A26: Мак изд Барилла №5 Спагетти 450г | B26: 8076809576093 | C26: 81.79 | D26: 119 | E26: 95 | F26: 100 | G26: 135 | H26: 94 | I26: 96 | J26: 105 | K26: 92
A27: Мак изд Барилла №98 Фузилли 450г | B27: 8076809576000 | C27: 81.79 | D27: 119 | E27: 108 | F27: 109 | G27: 115 | H27: 122 | I27: 199 | J27: 105 | K27: 92
A28: Мак изд Макфа Спагетти 400г | B28: 4601780010508 | C28: 49.51 | D28: 65 | E28: 68 | F28: 64 | H28: 77 | I28: 61 | J28: 80 | K28: 57
A29: Мак изд Макфа Спирали 400г | B29: 4601780006990 | C29: 49.51 | D29: 65 | E29: 68 | F29: 64 | G29: 68 | H29: 63 | I29: 62 | J29: 62 | K29: 56
A30: Мука Макфа в/с 2кг | B30: 4601780002565 | C30: 93 | D30: 119 | E30: 139 | F30: 107 | G30: 140 | H30: 157 | I30: 108 | J30: 130
A31: Мука Снежана в/с 2кг | B31: 1905000299036 | C31: 83.16 | D31: 99 (115) | G31: 110 | H31: 116 | I31: 108 | J31: 90
A32: Рис Агроальянс для плова 900г | B32: 4607072711535 | C32: 116.5 | D32: 135 (175) | F32: 202 | I32: 197 | J32: 145
A33: Рис Дарман шлифованный Премиум 2кг | B33: 4607157483784 | C33: 240 | D33: 299 | F33: 310 | I33: 293 | J33: 265
A34: Рис Дарман шлифованный Экстра 800г | B34: 4607157483029 | C34: 91.5 | D34: 115 | E34: 113 | F34: 123 | G34: 120 | J34: 110
A35: Рис Тамаша MIAD Индия мешочек 1кг | B35: 8906010700720 | C35: 165 | D35: 249 | E35: 250 | G35: 245 | H35: 244 | I35: 238 | J35: 230
A36: Сахар песок 1кг | B36: 2067468029354 | C36: 58.9 | D36: 65 | E36: 60 | F36: 64 | G36: 85 | I36: 78 | J36: 80
A37: Сода пищевая 500г | B37: 4640001890031 | C37: 38.16 | D37: 55 | E37: 55 | F37: 56 | G37: 55 | H37: 52 | I37: 53 | J37: 50
A38: Соль поваренная пищевая Помол №1 1кг Руссоль | B38: 4610007350228 | C38: 9.32 | D38: 17 | E38: 28 | F38: 22 | G38: 20 | H38: 19 | I38: 21 | J38: 18 | K38: 16
A39: Соль Экстра йодированная 500г | B39: 4607005090126 | C39: 65.38 | D39: 85 | F39: 84 | I39: 81 | J39: 55
A41: Пюре Агуша фруктовое пауч 160г Яблоко банан клубн земляника злаки | B41: 4690228110771 | C41: 63.16 | D41: 79 (135) | H41: 76 | I41: 80 | J41: 75
A42: Пюре ФрутоНяня 90г Яблоко натур. 4 мес д/пак | B42: 4600338006130 | C42: 47.48 | D42: 59 (95) | J42: 45
...

Sheet Продажи
A1: Штрихкод | B1: Количество_продаж | C1: Выручка | D1: Валовая_прибыль

Sheet Расчеты
A1: Наименование | B1: Штрихкод | C1: Закупочная_цена_ЗЯ | D1: Розничная_цена_ЗЯ | E1: Цена_7_Континент | F1: Цена_Европейский | G1: Цена_Тропики | H1: Цена_Мята | I1: Цена_Отличный | J1: Цена_Оптовик_Молоток | K1: Цена_Оптовик_Редукторный | L1: Средняя_цена_рынка | M1: Медианная_цена_рынка | N1: Мин_цена_конкурента | O1: Макс_цена_конкурента | P1: Отклонение_от_средней | Q1: Отклонение_от_медианы | R1: Отклонение_от_минимума | S1: Рейтинг_цены | T1: Текущая_наценка_% | U1: Текущая_маржа_% | V1: Валовая_прибыль_на_ед | W1: Количество_продаж | X1: Текущая_выручка | Y1: Текущая_валовая_прибыль | Z1: Текущая_маржа_общая_% | AA1: Целевая_маржа_сценарий_5 | AB1: Новая_цена_сценарий_1 | AC1: Наценка_сценарий_1 | AD1: Маржа_сценарий_1 | AE1: ВП_ед_сценарий_1 | AF1: Новая_цена_сценарий_2 | AG1: Наценка_сценарий_2 | AH1: Маржа_сценарий_2 | AI1: ВП_ед_сценарий_2 | AJ1: Новая_цена_сценарий_3 | AK1: Наценка_сценарий_3 | AL1: Маржа_сценарий_3 | AM1: ВП_ед_сценарий_3 | AN1: Новая_цена_сценарий_4 | AO1: Наценка_сценарий_4 | AP1: Маржа_сценарий_4 | AQ1: ВП_ед_сценарий_4 | AR1: Новая_цена_сценарий_5 | AS1: Наценка_сценарий_5 | AT1: Маржа_сценарий_5 | AU1: ВП_ед_сценарий_5 | AV1: Прогноз_выручка_1 | AW1: Прогноз_ВП_1 | AX1: Прогноз_выручка_2 | AY1: Прогноз_ВП_2 | AZ1: Прогноз_выручка_3 | BA1: Прогноз_ВП_3 | BB1: Прогноз_выручка_4 | BC1: Прогноз_ВП_4 | BD1: Прогноз_выручка_5 | BE1: Прогноз_ВП_5
A2: =XLOOKUP(B2,Исходные [1]данные!B:B,Исходные [1]данные!A:A,"") -> #NAME? | C2: =XLOOKUP(B2,Исходные [1]данные!B:B,Исходные [1]данные!C:C,"") -> #NAME? | D2: =XLOOKUP(B2,Исходные [1]данные!B:B,Исходные [1]данные!D:D,"") -> #NAME? | E2: =XLOOKUP(B2,Исходные [1]данные!B:B,Исходные [1]данные!E:E,"") -> #NAME? | F2: =XLOOKUP(B2,Исходные [1]данные!B:B,Исходные [1]данные!F:F,"") -> #NAME? | G2: =XLOOKUP(B2,Исходные [1]данные!B:B,Исходные [1]данные!G:G,"") -> #NAME? | H2: =XLOOKUP(B2,Исходные [1]данные!B:B,Исходные [1]данные!H:H,"") -> #NAME? | I2: =XLOOKUP(B2,Исходные [1]данные!B:B,Исходные [1]данные!I:I,"") -> #NAME? | J2: =XLOOKUP(B2,Исходные [1]данные!B:B,Исходные [1]данные!J:J,"") -> #NAME? | K2: =XLOOKUP(B2,Исходные [1]данные!B:B,Исходные [1]данные!K:K,"") -> #NAME? | L2: =IFERROR(AVERAGE(E2:K2),"") | M2: =IFERROR(MEDIAN(E2:K2),"") | N2: =IFERROR(MIN(E2:K2),"") | O2: =IFERROR(MAX(E2:K2),"") | P2: =IF(L2>0,(D2-L2)/L2,"") -> #NAME? | Q2: =IF(M2>0,(D2-M2)/M2,"") -> #NAME? | R2: =IF(N2>0,(D2-N2)/N2,"") -> #NAME? | S2: =IF(D2>0,RANK(D2,E2:K2),"") -> #NAME? | T2: =IF(C2>0,(D2-C2)/C2,"") -> #NAME? | U2: =IF(D2>0,(D2-C2)/D2,"") -> #NAME? | V2: =IF(AND(C2>0,D2>0),D2-C2,"") -> #NAME? | W2: =IFERROR(XLOOKUP(B2,Продажи!A:A,Продажи!B:B,""),"") | X2: =IF(W2>0,W2*D2,"") -> #VALUE! | Y2: =IF(W2>0,W2*V2,"") -> #VALUE! | Z2: =IF(X2>0,Y2/X2,"") -> #VALUE! | AB2: =L2 | AC2: =IF(AND(AB2>0,C2>0),(AB2-C2)/C2,"") -> #NAME? | AD2: =IF(AB2>0,(AB2-C2)/AB2,"") -> #VALUE! | AE2: =IF(AND(AB2>0,C2>0),AB2-C2,"") -> #NAME? | AF2: =M2 | AG2: =IF(AND(AF2>0,C2>0),(AF2-C2)/C2,"") -> #NAME? | AH2: =IF(AF2>0,(AF2-C2)/AF2,"") -> #VALUE! | AI2: =IF(AND(AF2>0,C2>0),AF2-C2,"") -> #NAME? | AJ2: =N2 | AK2: =IF(AND(AJ2>0,C2>0),(AJ2-C2)/C2,"") -> #NAME? | AL2: =IF(AJ2>0,(AJ2-C2)/AJ2,"") -> #VALUE! | AM2: =IF(AND(AJ2>0,C2>0),AJ2-C2,"") -> #NAME? | AO2: =IF(AND(AN2>0,C2>0),(AN2-C2)/C2,"") -> #NAME? | AP2: =IF(AN2>0,(AN2-C2)/AN2,"") | AQ2: =IF(AND(AN2>0,C2>0),AN2-C2,"") -> #NAME? | AR2: =IF(AA2>0,C2/(1-AA2),"") | AS2: =IF(AND(AR2>0,C2>0),(AR2-C2)/C2,"") -> #NAME? | AT2: =AA2 -> 0 | AU2: =IF(AND(AR2>0,C2>0),AR2-C2,"") -> #NAME? | AV2: =IF(W2>0,W2*AB2,"") -> #VALUE! | AW2: =IF(W2>0,W2*AE2,"") -> #VALUE! | AX2: =IF(W2>0,W2*AF2,"") -> #VALUE! | AY2: =IF(W2>0,W2*AI2,"") -> #VALUE! | AZ2: =IF(W2>0,W2*AJ2,"") -> #VALUE! | BA2: =IF(W2>0,W2*AM2,"") -> #VALUE! | BB2: =IF(W2>0,W2*AN2,"") -> #VALUE! | BC2: =IF(W2>0,W2*AQ2,"") -> #VALUE! | BD2: =IF(W2>0,W2*AR2,"") -> #VALUE! | BE2: =IF(W2>0,W2*AU2,"") -> #VALUE!

Sheet Dashboard
A1: KPI
A2: Позиций выше рынка | B2: =COUNTIF(Расчеты!P:P,">0") -> 0
A3: Позиций ниже рынка | B3: =COUNTIF(Расчеты!P:P,"<0") -> 0
A4: Средняя маржа | B4: =AVERAGE(Расчеты!Z:Z) -> #VALUE!
A5: Средняя наценка | B5: =AVERAGE(Расчеты!T:T) -> #NAME?
A6: Суммарная текущая ВП | B6: =SUM(Расчеты!Y:Y) -> #VALUE!
A7: Суммарная прогнозная ВП (сценарий 5) | B7: =SUM(Расчеты!BE:BE) -> #VALUE!

Sheet Сценарный анализ
A1: Сценарий | B1: Суммарная валовая прибыль | C1: Комментарий
A2: Текущая | B2: =SUM(Расчеты!Y:Y) -> #VALUE!
A3: Средняя цена рынка | B3: =SUM(Расчеты!AW:AW) -> #VALUE!
A4: Медианная цена рынка | B4: =SUM(Расчеты!AY:AY) -> #VALUE!
A5: Мин. цена конкурента | B5: =SUM(Расчеты!BA:BA) -> #VALUE!
A6: Произвольная цена | B6: =SUM(Расчеты!BC:BC) -> #VALUE!
A7: Целевая маржа | B7: =SUM(Расчеты!BE:BE) -> #VALUE!
